Workbook
Name CONSTR_MONTHS: Assumptions!$C$4
Name RETAIL_OPEN_M: Assumptions!$C$5
Name HOTEL_OPEN_M: Assumptions!$C$6
Name FIRST_CLOSING_M: Assumptions!$C$7
Name CLOSINGS_SPAN_M: Assumptions!$C$8
Name PERM_CONV_M: Assumptions!$C$9
Name EXIT_M: Assumptions!$C$10
Name UNITS_STUDIO: Assumptions!$C$13
Name SQFT_STUDIO: Assumptions!$C$14
Name PPSF_STUDIO: Assumptions!$C$15
Name UNITS_1BR: Assumptions!$C$16
Name SQFT_1BR: Assumptions!$C$17
Name PPSF_1BR: Assumptions!$C$18
Name UNITS_2BR: Assumptions!$C$19
Name SQFT_2BR: Assumptions!$C$20
Name PPSF_2BR: Assumptions!$C$21
Name UNITS_3BR: Assumptions!$C$22
Name SQFT_3BR: Assumptions!$C$23
Name PPSF_3BR: Assumptions!$C$24
Name UNITS_PH: Assumptions!$C$25
Name SQFT_PH: Assumptions!$C$26
Name PPSF_PH: Assumptions!$C$27
Name PARKING_SPACES: Assumptions!$C$28
Name PARKING_PRICE: Assumptions!$C$29
Name STORAGE_UNITS: Assumptions!$C$30
Name STORAGE_PRICE: Assumptions!$C$31
Name CLOSING_COST_PCT: Assumptions!$C$32
Name MARKETING_PCT: Assumptions!$C$33
Name LAND_COST: Assumptions!$C$36
Name ACQ_COST_PCT: Assumptions!$C$37
Name RES_GSF: Assumptions!$C$38
Name HOTEL_GSF: Assumptions!$C$39
Name RETAIL_GSF: Assumptions!$C$40
Name HC_PSF_RES: Assumptions!$C$41
Name HC_PSF_HOTEL: Assumptions!$C$42
Name HC_PSF_RETAIL: Assumptions!$C$43
Name CONTINGENCY_PCT: Assumptions!$C$44
Name SOFTCOST_PCT: Assumptions!$C$45
Name HOTEL_KEYS: Assumptions!$C$46
Name FFE_PER_KEY: Assumptions!$C$47
Name FFE_PSF_RETAIL: Assumptions!$C$48
Name DEVFEE_PCT: Assumptions!$C$49
Name LTC_PCT: Assumptions!$C$52
Name CT_SPREAD_PCT: Assumptions!$C$53
Name SOFR_FLOOR_PCT: Assumptions!$C$54
Name AVG_DRAWN_FRAC: Assumptions!$C$55
Name CT_COSTS_PCT: Assumptions!$C$56
Name PERM_LTV: Assumptions!$C$59
Name PERM_DSCR: Assumptions!$C$60
Name PERM_DY: Assumptions!$C$61
Name PERM_RATE_PCT: Assumptions!$C$62
Name PERM_AMORT_YRS: Assumptions!$C$63
Name PERM_COSTS_PCT: Assumptions!$C$64
Name ADR_Y1: Assumptions!$C$67
Name ADR_GROWTH_PCT: Assumptions!$C$68
Name OCC_Y1: Assumptions!$C$69
Name OCC_Y2: Assumptions!$C$70
Name OCC_STAB: Assumptions!$C$71
Name FB_REV_PCT: Assumptions!$C$72
Name OTHER_REV_PCT: Assumptions!$C$73

Sheet Cover
A1: Elite Luxury Mixed-Use Development Model
A3: ILLUSTRATIVE TEMPLATE — NOT A LIVE DEAL, NOT AN OFFERING, NOT INVESTMENT ADVICE. The SOFR forward curve is a placeholder assumption, not a live Chatham quote; paste live forwards into the SOFR sheet. All figures are illustrative defaults.
A5: Sheets
A6: Cover | B6: formula
A7: Assumptions | B7: input
A8: SOFR | B8: input
A9: SourcesUses | B9: formula
A10: SpendCurve | B10: formula
A11: CondoSellout | B11: formula
A12: RetailProForma | B12: formula
A13: HotelProForma | B13: formula
A14: ConstructionDebt | B14: formula
A15: PermanentDebt | B15: formula
A16: HotelValuation | B16: formula
A17: RetailValuation | B17: formula
... A21: Checks | B21: formula
A23: Blue font marks an input. Every other amount is an Excel formula.
A24: Condo economics are sellout revenue net of costs. No cap rate is applied to condos.
A25: XIRR on Returns is an output. It is not a waterfall distribution trigger.

Sheet Assumptions
A1: Assumptions
A2: Name | B2: Unit | C2: Value | D2: Note
A3: Timeline
A4: CONSTR_MONTHS | B4: months | C4: 30 | D4: Construction duration, months 1 through this month
A5: RETAIL_OPEN_M | B5: month | C5: 29 | D5: First month of retail operations
A6: HOTEL_OPEN_M | B6: month | C6: 31 | D6: First month of hotel operations
A7: FIRST_CLOSING_M | B7: month | C7: 33 | D7: First condo closing month
A8: CLOSINGS_SPAN_M | B8: months | C8: 36 | D8: Sellout length; last closing is first + span - 1
A9: PERM_CONV_M | B9: month | C9: 72 | D9: Permanent loan conversion month
A10: EXIT_M | B10: month | C10: 84 | D10: Terminal sale month; fixed at the last model column
A12: Condo program
A13: UNITS_STUDIO | B13: units | C13: 36 | D13: Studio inventory
A14: SQFT_STUDIO | B14: SF | C14: 650 | D14: Studio average size
A15: PPSF_STUDIO | B15: $/SF | C15: 1600 | D15: Studio contract price
A16: UNITS_1BR | B16: units | C16: 72 | D16: One-bedroom inventory
A17: SQFT_1BR | B17: SF | C17: 950 | D17: One-bedroom average size
A18: PPSF_1BR | B18: $/SF | C18: 1750 | D18: One-bedroom contract price
A19: UNITS_2BR | B19: units | C19: 54 | D19: Two-bedroom inventory
A20: SQFT_2BR | B20: SF | C20: 1450 | D20: Two-bedroom average size
A21: PPSF_2BR | B21: $/SF | C21: 1900 | D21: Two-bedroom contract price
A22: UNITS_3BR | B22: units | C22: 14 | D22: Three-bedroom inventory
A23: SQFT_3BR | B23: SF | C23: 2100 | D23: Three-bedroom average size
A24: PPSF_3BR | B24: $/SF | C24: 2200 | D24: Three-bedroom contract price
... A33: MARKETING_PCT | B33: % of gross | C33: 0.015 | D33: Marketing cost rate
A35: Development budget
A36: LAND_COST | B36: $ | C36: 85000000 | D36: Land, funded at month 1
A37: ACQ_COST_PCT | B37: % of land | C37: 0.01 | D37: Acquisition costs
A38: RES_GSF | B38: SF | C38: 240000 | D38: Residential gross area
A39: HOTEL_GSF | B39: SF | C39: 150000 | D39: Hotel gross area
A40: RETAIL_GSF | B40: SF | C40: 25000 | D40: Retail gross area
A41: HC_PSF_RES | B41: $/SF | C41: 700 | D41: Residential hard-cost unit rate
A42: HC_PSF_HOTEL | B42: $/SF | C42: 850 | D42: Hotel hard-cost unit rate
A43: HC_PSF_RETAIL | B43: $/SF | C43: 600 | D43: Retail hard-cost unit rate
A44: CONTINGENCY_PCT | B44: % of hard | C44: 0.04 | D44: Contingency
A45: SOFTCOST_PCT | B45: % of hard | C45: 0.12 | D45: Soft costs
A46: HOTEL_KEYS | B46: keys | C46: 200 | D46: Hotel keys
A47: FFE_PER_KEY | B47: $/key | C47: 45000 | D47: Hotel FF&E
... A49: DEVFEE_PCT | B49: % of fee base | C49: 0.04 | D49: Fee base is land, acquisition, hard, contingency, soft, and FF&E
A51: Construction debt
A52: LTC_PCT | B52: % of uses | C52: 0.6 | D52: Loan-to-cost, including the interest reserve
...

Sheet SOFR
A1: SOFR
A2: =ROW()-1 | B2: =EOMONTH(DATE(2026,1,1),A2-1) | C2: 0.043 | D2: ASSUMPTION — placeholder forward; not a live Chatham quote. Paste Chatham forwards here. | E2: Paste target. Placeholder path is 4.30% at month 1 gliding linearly to 3.60% at month 24, then flat. Not a live quote.
A3: =ROW()-1 | B3: =EOMONTH(DATE(2026,1,1),A3-1) | C3: 0.042695652 | D3: ASSUMPTION — placeholder forward; not a live Chatham quote. Paste Chatham forwards here.
A4: =ROW()-1 | B4: =EOMONTH(DATE(2026,1,1),A4-1) | C4: 0.042391304 | D4: ASSUMPTION — placeholder forward; not a live Chatham quote. Paste Chatham forwards here.
A5: =ROW()-1 | B5: =EOMONTH(DATE(2026,1,1),A5-1) | C5: 0.042086957 | D5: ASSUMPTION — placeholder forward; not a live Chatham quote. Paste Chatham forwards here.
A6: =ROW()-1 | B6: =EOMONTH(DATE(2026,1,1),A6-1) | C6: 0.041782609 | D6: ASSUMPTION — placeholder forward; not a live Chatham quote. Paste Chatham forwards here.
A7: =ROW()-1 | B7: =EOMONTH(DATE(2026,1,1),A7-1) | C7: 0.041478261 | D7: ASSUMPTION — placeholder forward; not a live Chatham quote. Paste Chatham forwards here.
A8: =ROW()-1 | B8: =EOMONTH(DATE(2026,1,1),A8-1) | C8: 0.041173913 | D8: ASSUMPTION — placeholder forward; not a live Chatham quote. Paste Chatham forwards here.
A9: =ROW()-1 | B9: =EOMONTH(DATE(2026,1,1),A9-1) | C9: 0.040869565 | D9: ASSUMPTION — placeholder forward; not a live Chatham quote. Paste Chatham forwards here.
A10: =ROW()-1 | B10: =EOMONTH(DATE(2026,1,1),A10-1) | C10: 0.040565217 | D10: ASSUMPTION — placeholder forward; not a live Chatham quote. Paste Chatham forwards here.
A11: =ROW()-1 | B11: =EOMONTH(DATE(2026,1,1),A11-1) | C11: 0.04026087 | D11: ASSUMPTION — placeholder forward; not a live Chatham quote. Paste Chatham forwards here.
A12: =ROW()-1 | B12: =EOMONTH(DATE(2026,1,1),A12-1) | C12: 0.039956522 | D12: ASSUMPTION — placeholder forward; not a live Chatham quote. Paste Chatham forwards here.
A13: =ROW()-1 | B13: =EOMONTH(DATE(2026,1,1),A13-1) | C13: 0.039652174 | D13: ASSUMPTION — placeholder forward; not a live Chatham quote. Paste Chatham forwards here.
A14: =ROW()-1 | B14: =EOMONTH(DATE(2026,1,1),A14-1) | C14: 0.039347826 | D14: ASSUMPTION — placeholder forward; not a live Chatham quote. Paste Chatham forwards here.
... A85: =ROW()-1 | B85: =EOMONTH(DATE(2026,1,1),A85-1) | C85: 0.036 | D85: ASSUMPTION — placeholder forward; not a live Chatham quote. Paste Chatham forwards here.

Sheet SourcesUses
A1: SourcesUses
A2: Line | B2: Unit | C2: Amount | D2: Definition
A4: Land | B4: $ | C4: =LAND_COST | D4: Named input
A5: Acquisition costs | B5: $ | C5: =LAND_COST*ACQ_COST_PCT | D5: Land times acquisition rate
A6: Land and acquisition | B6: $ | C6: =C4+C5 | D6: Funded at month 1
A7: Hard costs residential | B7: $ | C7: =RES_GSF*HC_PSF_RES | D7: Area times unit rate
A8: Hard costs hotel | B8: $ | C8: =HOTEL_GSF*HC_PSF_HOTEL | D8: Area times unit rate
A9: Hard costs retail | B9: $ | C9: =RETAIL_GSF*HC_PSF_RETAIL | D9: Area times unit rate
A10: Hard costs | B10: $ | C10: =C7+C8+C9 | D10: Sum of hard-cost lines
A11: Contingency | B11: $ | C11: =CONTINGENCY_PCT*C10 | D11: Percent of hard costs
A12: Soft costs | B12: $ | C12: =SOFTCOST_PCT*C10 | D12: Percent of hard costs
A13: FF&E hotel | B13: $ | C13: =HOTEL_KEYS*FFE_PER_KEY | D13: Keys times allowance
A14: FF&E retail | B14: $ | C14: =RETAIL_GSF*FFE_PSF_RETAIL | D14: Area times allowance
A15: FF&E | B15: $ | C15: =C13+C14 | D15: Hotel plus retail
A16: Developer fee base | B16: $ | C16: =C6+C10+C11+C12+C15 | D16: Land, acquisition, hard, contingency, soft, FF&E
A17: Developer fee | B17: $ | C17: =DEVFEE_PCT*C16 | D17: Percent of fee base
A18: Uses excluding interest | B18: $ | C18: =C16+C17 | D18: Fee base plus developer fee
A19: Average SOFR during construction | B19: % | C19: =AVERAGE(SOFR!$C$2:INDEX(SOFR!$C$2:$C$85,CONSTR_MONTHS)) | D19: Arithmetic average of the paste-target forwards
A20: Interest reserve | B20: $ | C20: =LTC_PCT*C18*((C19+CT_SPREAD_PCT)/12)*CONSTR_MONTHS*AVG_DRAWN_FRAC | D20: Linear estimate. No circular interest calculation.
A21: Total uses | B21: $ | C21: =(C18+C20)/(1-LTC_PCT*CT_COSTS_PCT) | D21: Closed form so commitment = LTC% x total uses, with loan costs inside uses.
A22: Construction commitment | B22: $ | C22: =LTC_PCT*C21 | D22: LTC times total uses, including the interest reserve
A23: Construction loan costs | B23: $ | C23: =CT_COSTS_PCT*C22 | D23: Percent of commitment. Permanent financing costs are not here.
A24: Uses component sum | B24: $ | C24: =C18+C20+C23 | D24: Ex-interest plus reserve plus loan costs
A25: Uses tie-out | B25: $ | C25: =C24-C21 | D25: Must be zero
A26: Sources
A27: Source: construction loan | B27: $ | C27: =C22 | D27: Commitment
A28: Source: equity | B28: $ | C28: =C21-C22 | D28: Total uses minus commitment. Contributed at month 1.
A29: Total sources | B29: $ | C29: =C27+C28 | D29: Loan plus equity
A30: GP equity | B30: $ | C30: =C28*GP_EQUITY_PCT | D30: Co-invest share
A31: LP equity | B31: $ | C31: =C28*(1-GP_EQUITY_PCT) | D31: Remainder of equity
A32: Non-land uses on the spend curve | B32: $ | C32: =C10+C11+C12+C15+C17 | D32: Hard, contingency, soft, FF&E, and fee
A33: Sources minus uses | B33: $ | C33: =C29-C21 | D33: Must be zero

Sheet SpendCurve
A1: SpendCurve | D1: Land and loan costs at month 1. Other non-interest uses follow S(t)=(t/CONSTR_MONTHS)^2.2.
A2: Month | B2: index | C2: =COLUMN()-2 | D2: =COLUMN()-2 | E2: =COLUMN()-2 | F2: =COLUMN()-2 | G2: =COLUMN()-2 | H2: =COLUMN()-2 | I2: =COLUMN()-2 | J2: =COLUMN()-2 | ... CH2: =COLUMN()-2
A3: Date | B3: month-end | C3: =EOMONTH(DATE(2026,1,1),C2-1) | D3: =EOMONTH(DATE(2026,1,1),D2-1) | E3: =EOMONTH(DATE(2026,1,1),E2-1) | F3: =EOMONTH(DATE(2026,1,1),F2-1) | G3: =EOMONTH(DATE(2026,1,1),G2-1) | H3: =EOMONTH(DATE(2026,1,1),H2-1) | I3: =EOMONTH(DATE(2026,1,1),I2-1) | J3: =EOMONTH(DATE(2026,1,1),J2-1) | ... CH3: =EOMONTH(DATE(2026,1,1),CH2-1)
A4: Cumulative spend fraction S(t) | B4: fraction | C4: =IF(C2>=CONSTR_MONTHS,1,(C2/CONSTR_MONTHS)^2.2) | D4: =IF(D2>=CONSTR_MONTHS,1,(D2/CONSTR_MONTHS)^2.2) | E4: =IF(E2>=CONSTR_MONTHS,1,(E2/CONSTR_MONTHS)^2.2) | F4: =IF(F2>=CONSTR_MONTHS,1,(F2/CONSTR_MONTHS)^2.2) | G4: =IF(G2>=CONSTR_MONTHS,1,(G2/CONSTR_MONTHS)^2.2) | H4: =IF(H2>=CONSTR_MONTHS,1,(H2/CONSTR_MONTHS)^2.2) | I4: =IF(I2>=CONSTR_MONTHS,1,(I2/CONSTR_MONTHS)^2.2) | J4: =IF(J2>=CONSTR_MONTHS,1,(J2/CONSTR_MONTHS)^2.2) | ... CH4: =IF(CH2>=CONSTR_MONTHS,1,(CH2/CONSTR_MONTHS)^2.2)
A5: Prior cumulative fraction | B5: fraction | C5: =0 | D5: =IF(D2-1>=CONSTR_MONTHS,1,((D2-1)/CONSTR_MONTHS)^2.2) | E5: =IF(E2-1>=CONSTR_MONTHS,1,((E2-1)/CONSTR_MONTHS)^2.2) | F5: =IF(F2-1>=CONSTR_MONTHS,1,((F2-1)/CONSTR_MONTHS)^2.2) | G5: =IF(G2-1>=CONSTR_MONTHS,1,((G2-1)/CONSTR_MONTHS)^2.2) | H5: =IF(H2-1>=CONSTR_MONTHS,1,((H2-1)/CONSTR_MONTHS)^2.2) | I5: =IF(I2-1>=CONSTR_MONTHS,1,((I2-1)/CONSTR_MONTHS)^2.2) | J5: =IF(J2-1>=CONSTR_MONTHS,1,((J2-1)/CONSTR_MONTHS)^2.2) | K5: =IF(K2-1>=CONSTR_MONTHS,1,((K2-1)/CONSTR_MONTHS)^2.2) | ... CH5: =IF(CH2-1>=CONSTR_MONTHS,1,((CH2-1)/CONSTR_MONTHS)^2.2)
A6: Monthly weight | B6: fraction | C6: =C4-C5 | D6: =D4-D5 | E6: =E4-E5 | F6: =F4-F5 | G6: =G4-G5 | H6: =H4-H5 | I6: =I4-I5 | J6: =J4-J5 | ... CH6: =CH4-CH5
A7: Land and acquisition | B7: $ | C7: =IF(C2=1,SourcesUses!$C$6,0) | D7: =IF(D2=1,SourcesUses!$C$6,0) | E7: =IF(E2=1,SourcesUses!$C$6,0) | F7: =IF(F2=1,SourcesUses!$C$6,0) | G7: =IF(G2=1,SourcesUses!$C$6,0) | H7: =IF(H2=1,SourcesUses!$C$6,0) | I7: =IF(I2=1,SourcesUses!$C$6,0) | J7: =IF(J2=1,SourcesUses!$C$6,0) | ... CH7: =IF(CH2=1,SourcesUses!$C$6,0)
A8: Non-land uses | B8: $ | C8: =SourcesUses!$C$32*C6 | D8: =SourcesUses!$C$32*D6 | E8: =SourcesUses!$C$32*E6 | F8: =SourcesUses!$C$32*F6 | G8: =SourcesUses!$C$32*G6 | H8: =SourcesUses!$C$32*H6 | I8: =SourcesUses!$C$32*I6 | J8: =SourcesUses!$C$32*J6 | ... CH8: =SourcesUses!$C$32*CH6
A9: Construction loan costs | B9: $ | C9: =IF(C2=1,SourcesUses!$C$23,0) | D9: =IF(D2=1,SourcesUses!$C$23,0) | E9: =IF(E2=1,SourcesUses!$C$23,0) | F9: =IF(F2=1,SourcesUses!$C$23,0) | G9: =IF(G2=1,SourcesUses!$C$23,0) | H9: =IF(H2=1,SourcesUses!$C$23,0) | I9: =IF(I2=1,SourcesUses!$C$23,0) | J9: =IF(J2=1,SourcesUses!$C$23,0) | ... CH9: =IF(CH2=1,SourcesUses!$C$23,0)
A10: Budget spend | B10: $ | C10: =C7+C8+C9 | D10: =D7+D8+D9 | E10: =E7+E8+E9 | F10: =F7+F8+F9 | G10: =G7+G8+G9 | H10: =H7+H8+H9 | I10: =I7+I8+I9 | J10: =J7+J8+J9 | ... CH10: =CH7+CH8+CH9

Sheet CondoSellout
A1: CondoSellout
A2: Month | B2: index | C2: =COLUMN()-2 | D2: =COLUMN()-2 | E2: =COLUMN()-2 | F2: =COLUMN()-2 | G2: =COLUMN()-2 | H2: =COLUMN()-2 | I2: =COLUMN()-2 | J2: =COLUMN()-2 | ... CH2: =COLUMN()-2
A3: Date | B3: month-end | C3: =EOMONTH(DATE(2026,1,1),C2-1) | D3: =EOMONTH(DATE(2026,1,1),D2-1) | E3: =EOMONTH(DATE(2026,1,1),E2-1) | F3: =EOMONTH(DATE(2026,1,1),F2-1) | G3: =EOMONTH(DATE(2026,1,1),G2-1) | H3: =EOMONTH(DATE(2026,1,1),H2-1) | I3: =EOMONTH(DATE(2026,1,1),I2-1) | J3: =EOMONTH(DATE(2026,1,1),J2-1) | ... CH3: =EOMONTH(DATE(2026,1,1),CH2-1)
A4: Studio closings | B4: units | C4: =IF(AND(C2>=FIRST_CLOSING_M,C2<FIRST_CLOSING_M+CLOSINGS_SPAN_M),ROUNDDOWN(UNITS_STUDIO/CLOSINGS_SPAN_M,0)+IF(C2-FIRST_CLOSING_M+1<=UNITS_STUDIO-ROUNDDOWN(UNITS_STUDIO/CLOSINGS_SPAN_M,0)*CLOSINGS_SPAN_M,1,0),0) | D4: =IF(AND(D2>=FIRST_CLOSING_M,D2<FIRST_CLOSING_M+CLOSINGS_SPAN_M),ROUNDDOWN(UNITS_STUDIO/CLOSINGS_SPAN_M,0)+IF(D2-FIRST_CLOSING_M+1<=UNITS_STUDIO-ROUNDDOWN(UNITS_STUDIO/CLOSINGS_SPAN_M,0)*CLOSINGS_SPAN_M,1,0),0) | E4: =IF(AND(E2>=FIRST_CLOSING_M,E2<FIRST_CLOSING_M+CLOSINGS_SPAN_M),ROUNDDOWN(UNITS_STUDIO/CLOSINGS_SPAN_M,0)+IF(E2-FIRST_CLOSING_M+1<=UNITS_STUDIO-ROUNDDOWN(UNITS_STUDIO/CLOSINGS_SPAN_M,0)*CLOSINGS_SPAN_M,1,0),0) | F4: =IF(AND(F2>=FIRST_CLOSING_M,F2<FIRST_CLOSING_M+CLOSINGS_SPAN_M),ROUNDDOWN(UNITS_STUDIO/CLOSINGS_SPAN_M,0)+IF(F2-FIRST_CLOSING_M+1<=UNITS_STUDIO-ROUNDDOWN(UNITS_STUDIO/CLOSINGS_SPAN_M,0)*CLOSINGS_SPAN_M,1,0),0) | G4: =IF(AND(G2>=FIRST_CLOSING_M,G2<FIRST_CLOSING_M+CLOSINGS_SPAN_M),ROUNDDOWN(UNITS_STUDIO/CLOSINGS_SPAN_M,0)+IF(G2-FIRST_CLOSING_M+1<=UNITS_STUDIO-ROUNDDOWN(UNITS_STUDIO/CLOSINGS_SPAN_M,0)*CLOSINGS_SPAN_M,1,0),0) | H4: =IF(AND(H2>=FIRST_CLOSING_M,H2<FIRST_CLOSING_M+CLOSINGS_SPAN_M),ROUNDDOWN(UNITS_STUDIO/CLOSINGS_SPAN_M,0)+IF(H2-FIRST_CLOSING_M+1<=UNITS_STUDIO-ROUNDDOWN(UNITS_STUDIO/CLOSINGS_SPAN_M,0)*CLOSINGS_SPAN_M,1,0),0) | I4: =IF(AND(I2>=FIRST_CLOSING_M,I2<FIRST_CLOSING_M+CLOSINGS_SPAN_M),ROUNDDOWN(UNITS_STUDIO/CLOSINGS_SPAN_M,0)+IF(I2-FIRST_CLOSING_M+1<=UNITS_STUDIO-ROUNDDOWN(UNITS_STUDIO/CLOSINGS_SPAN_M,0)*CLOSINGS_SPAN_M,1,0),0) | J4: =IF(AND(J2>=FIRST_CLOSING_M,J2<FIRST_CLOSING_M+CLOSINGS_SPAN_M),ROUNDDOWN(UNITS_STUDIO/CLOSINGS_SPAN_M,0)+IF(J2-FIRST_CLOSING_M+1<=UNITS_STUDIO-ROUNDDOWN(UNITS_STUDIO/CLOSINGS_SPAN_M,0)*CLOSINGS_SPAN_M,1,0),0) | ... CH4: =IF(AND(CH2>=FIRST_CLOSING_M,CH2<FIRST_CLOSING_M+CLOSINGS_SPAN_M),ROUNDDOWN(UNITS_STUDIO/CLOSINGS_SPAN_M,0)+IF(CH2-FIRST_CLOSING_M+1<=UNITS_STUDIO-ROUNDDOWN(UNITS_STUDIO/CLOSINGS_SPAN_M,0)*CLOSINGS_SPAN_M,1,0),0)
A5: One-bedroom closings | B5: units | C5: =IF(AND(C2>=FIRST_CLOSING_M,C2<FIRST_CLOSING_M+CLOSINGS_SPAN_M),ROUNDDOWN(UNITS_1BR/CLOSINGS_SPAN_M,0)+IF(C2-FIRST_CLOSING_M+1<=UNITS_1BR-ROUNDDOWN(UNITS_1BR/CLOSINGS_SPAN_M,0)*CLOSINGS_SPAN_M,1,0),0) | D5: =IF(AND(D2>=FIRST_CLOSING_M,D2<FIRST_CLOSING_M+CLOSINGS_SPAN_M),ROUNDDOWN(UNITS_1BR/CLOSINGS_SPAN_M,0)+IF(D2-FIRST_CLOSING_M+1<=UNITS_1BR-ROUNDDOWN(UNITS_1BR/CLOSINGS_SPAN_M,0)*CLOSINGS_SPAN_M,1,0),0) | E5: =IF(AND(E2>=FIRST_CLOSING_M,E2<FIRST_CLOSING_M+CLOSINGS_SPAN_M),ROUNDDOWN(UNITS_1BR/CLOSINGS_SPAN_M,0)+IF(E2-FIRST_CLOSING_M+1<=UNITS_1BR-ROUNDDOWN(UNITS_1BR/CLOSINGS_SPAN_M,0)*CLOSINGS_SPAN_M,1,0),0) | F5: =IF(AND(F2>=FIRST_CLOSING_M,F2<FIRST_CLOSING_M+CLOSINGS_SPAN_M),ROUNDDOWN(UNITS_1BR/CLOSINGS_SPAN_M,0)+IF(F2-FIRST_CLOSING_M+1<=UNITS_1BR-ROUNDDOWN(UNITS_1BR/CLOSINGS_SPAN_M,0)*CLOSINGS_SPAN_M,1,0),0) | G5: =IF(AND(G2>=FIRST_CLOSING_M,G2<FIRST_CLOSING_M+CLOSINGS_SPAN_M),ROUNDDOWN(UNITS_1BR/CLOSINGS_SPAN_M,0)+IF(G2-FIRST_CLOSING_M+1<=UNITS_1BR-ROUNDDOWN(UNITS_1BR/CLOSINGS_SPAN_M,0)*CLOSINGS_SPAN_M,1,0),0) | H5: =IF(AND(H2>=FIRST_CLOSING_M,H2<FIRST_CLOSING_M+CLOSINGS_SPAN_M),ROUNDDOWN(UNITS_1BR/CLOSINGS_SPAN_M,0)+IF(H2-FIRST_CLOSING_M+1<=UNITS_1BR-ROUNDDOWN(UNITS_1BR/CLOSINGS_SPAN_M,0)*CLOSINGS_SPAN_M,1,0),0) | I5: =IF(AND(I2>=FIRST_CLOSING_M,I2<FIRST_CLOSING_M+CLOSINGS_SPAN_M),ROUNDDOWN(UNITS_1BR/CLOSINGS_SPAN_M,0)+IF(I2-FIRST_CLOSING_M+1<=UNITS_1BR-ROUNDDOWN(UNITS_1BR/CLOSINGS_SPAN_M,0)*CLOSINGS_SPAN_M,1,0),0) | J5: =IF(AND(J2>=FIRST_CLOSING_M,J2<FIRST_CLOSING_M+CLOSINGS_SPAN_M),ROUNDDOWN(UNITS_1BR/CLOSINGS_SPAN_M,0)+IF(J2-FIRST_CLOSING_M+1<=UNITS_1BR-ROUNDDOWN(UNITS_1BR/CLOSINGS_SPAN_M,0)*CLOSINGS_SPAN_M,1,0),0) | ... CH5: =IF(AND(CH2>=FIRST_CLOSING_M,CH2<FIRST_CLOSING_M+CLOSINGS_SPAN_M),ROUNDDOWN(UNITS_1BR/CLOSINGS_SPAN_M,0)+IF(CH2-FIRST_CLOSING_M+1<=UNITS_1BR-ROUNDDOWN(UNITS_1BR/CLOSINGS_SPAN_M,0)*CLOSINGS_SPAN_M,1,0),0)
A6: Two-bedroom closings | B6: units | C6: =IF(AND(C2>=FIRST_CLOSING_M,C2<FIRST_CLOSING_M+CLOSINGS_SPAN_M),ROUNDDOWN(UNITS_2BR/CLOSINGS_SPAN_M,0)+IF(C2-FIRST_CLOSING_M+1<=UNITS_2BR-ROUNDDOWN(UNITS_2BR/CLOSINGS_SPAN_M,0)*CLOSINGS_SPAN_M,1,0),0) | D6: =IF(AND(D2>=FIRST_CLOSING_M,D2<FIRST_CLOSING_M+CLOSINGS_SPAN_M),ROUNDDOWN(UNITS_2BR/CLOSINGS_SPAN_M,0)+IF(D2-FIRST_CLOSING_M+1<=UNITS_2BR-ROUNDDOWN(UNITS_2BR/CLOSINGS_SPAN_M,0)*CLOSINGS_SPAN_M,1,0),0) | E6: =IF(AND(E2>=FIRST_CLOSING_M,E2<FIRST_CLOSING_M+CLOSINGS_SPAN_M),ROUNDDOWN(UNITS_2BR/CLOSINGS_SPAN_M,0)+IF(E2-FIRST_CLOSING_M+1<=UNITS_2BR-ROUNDDOWN(UNITS_2BR/CLOSINGS_SPAN_M,0)*CLOSINGS_SPAN_M,1,0),0) | F6: =IF(AND(F2>=FIRST_CLOSING_M,F2<FIRST_CLOSING_M+CLOSINGS_SPAN_M),ROUNDDOWN(UNITS_2BR/CLOSINGS_SPAN_M,0)+IF(F2-FIRST_CLOSING_M+1<=UNITS_2BR-ROUNDDOWN(UNITS_2BR/CLOSINGS_SPAN_M,0)*CLOSINGS_SPAN_M,1,0),0) | G6: =IF(AND(G2>=FIRST_CLOSING_M,G2<FIRST_CLOSING_M+CLOSINGS_SPAN_M),ROUNDDOWN(UNITS_2BR/CLOSINGS_SPAN_M,0)+IF(G2-FIRST_CLOSING_M+1<=UNITS_2BR-ROUNDDOWN(UNITS_2BR/CLOSINGS_SPAN_M,0)*CLOSINGS_SPAN_M,1,0),0) | H6: =IF(AND(H2>=FIRST_CLOSING_M,H2<FIRST_CLOSING_M+CLOSINGS_SPAN_M),ROUNDDOWN(UNITS_2BR/CLOSINGS_SPAN_M,0)+IF(H2-FIRST_CLOSING_M+1<=UNITS_2BR-ROUNDDOWN(UNITS_2BR/CLOSINGS_SPAN_M,0)*CLOSINGS_SPAN_M,1,0),0) | I6: =IF(AND(I2>=FIRST_CLOSING_M,I2<FIRST_CLOSING_M+CLOSINGS_SPAN_M),ROUNDDOWN(UNITS_2BR/CLOSINGS_SPAN_M,0)+IF(I2-FIRST_CLOSING_M+1<=UNITS_2BR-ROUNDDOWN(UNITS_2BR/CLOSINGS_SPAN_M,0)*CLOSINGS_SPAN_M,1,0),0) | J6: =IF(AND(J2>=FIRST_CLOSING_M,J2<FIRST_CLOSING_M+CLOSINGS_SPAN_M),ROUNDDOWN(UNITS_2BR/CLOSINGS_SPAN_M,0)+IF(J2-FIRST_CLOSING_M+1<=UNITS_2BR-ROUNDDOWN(UNITS_2BR/CLOSINGS_SPAN_M,0)*CLOSINGS_SPAN_M,1,0),0) | ... CH6: =IF(AND(CH2>=FIRST_CLOSING_M,CH2<FIRST_CLOSING_M+CLOSINGS_SPAN_M),ROUNDDOWN(UNITS_2BR/CLOSINGS_SPAN_M,0)+IF(CH2-FIRST_CLOSING_M+1<=UNITS_2BR-ROUNDDOWN(UNITS_2BR/CLOSINGS_SPAN_M,0)*CLOSINGS_SPAN_M,1,0),0)
A7: Three-bedroom closings | B7: units | C7: =IF(AND(C2>=FIRST_CLOSING_M,C2<FIRST_CLOSING_M+CLOSINGS_SPAN_M),ROUNDDOWN(UNITS_3BR/CLOSINGS_SPAN_M,0)+IF(C2-FIRST_CLOSING_M+1<=UNITS_3BR-ROUNDDOWN(UNITS_3BR/CLOSINGS_SPAN_M,0)*CLOSINGS_SPAN_M,1,0),0) | D7: =IF(AND(D2>=FIRST_CLOSING_M,D2<FIRST_CLOSING_M+CLOSINGS_SPAN_M),ROUNDDOWN(UNITS_3BR/CLOSINGS_SPAN_M,0)+IF(D2-FIRST_CLOSING_M+1<=UNITS_3BR-ROUNDDOWN(UNITS_3BR/CLOSINGS_SPAN_M,0)*CLOSINGS_SPAN_M,1,0),0) | E7: =IF(AND(E2>=FIRST_CLOSING_M,E2<FIRST_CLOSING_M+CLOSINGS_SPAN_M),ROUNDDOWN(UNITS_3BR/CLOSINGS_SPAN_M,0)+IF(E2-FIRST_CLOSING_M+1<=UNITS_3BR-ROUNDDOWN(UNITS_3BR/CLOSINGS_SPAN_M,0)*CLOSINGS_SPAN_M,1,0),0) | F7: =IF(AND(F2>=FIRST_CLOSING_M,F2<FIRST_CLOSING_M+CLOSINGS_SPAN_M),ROUNDDOWN(UNITS_3BR/CLOSINGS_SPAN_M,0)+IF(F2-FIRST_CLOSING_M+1<=UNITS_3BR-ROUNDDOWN(UNITS_3BR/CLOSINGS_SPAN_M,0)*CLOSINGS_SPAN_M,1,0),0) | G7: =IF(AND(G2>=FIRST_CLOSING_M,G2<FIRST_CLOSING_M+CLOSINGS_SPAN_M),ROUNDDOWN(UNITS_3BR/CLOSINGS_SPAN_M,0)+IF(G2-FIRST_CLOSING_M+1<=UNITS_3BR-ROUNDDOWN(UNITS_3BR/CLOSINGS_SPAN_M,0)*CLOSINGS_SPAN_M,1,0),0) | H7: =IF(AND(H2>=FIRST_CLOSING_M,H2<FIRST_CLOSING_M+CLOSINGS_SPAN_M),ROUNDDOWN(UNITS_3BR/CLOSINGS_SPAN_M,0)+IF(H2-FIRST_CLOSING_M+1<=UNITS_3BR-ROUNDDOWN(UNITS_3BR/CLOSINGS_SPAN_M,0)*CLOSINGS_SPAN_M,1,0),0) | I7: =IF(AND(I2>=FIRST_CLOSING_M,I2<FIRST_CLOSING_M+CLOSINGS_SPAN_M),ROUNDDOWN(UNITS_3BR/CLOSINGS_SPAN_M,0)+IF(I2-FIRST_CLOSING_M+1<=UNITS_3BR-ROUNDDOWN(UNITS_3BR/CLOSINGS_SPAN_M,0)*CLOSINGS_SPAN_M,1,0),0) | J7: =IF(AND(J2>=FIRST_CLOSING_M,J2<FIRST_CLOSING_M+CLOSINGS_SPAN_M),ROUNDDOWN(UNITS_3BR/CLOSINGS_SPAN_M,0)+IF(J2-FIRST_CLOSING_M+1<=UNITS_3BR-ROUNDDOWN(UNITS_3BR/CLOSINGS_SPAN_M,0)*CLOSINGS_SPAN_M,1,0),0) | ... CH7: =IF(AND(CH2>=FIRST_CLOSING_M,CH2<FIRST_CLOSING_M+CLOSINGS_SPAN_M),ROUNDDOWN(UNITS_3BR/CLOSINGS_SPAN_M,0)+IF(CH2-FIRST_CLOSING_M+1<=UNITS_3BR-ROUNDDOWN(UNITS_3BR/CLOSINGS_SPAN_M,0)*CLOSINGS_SPAN_M,1,0),0)
A8: Penthouse closings | B8: units | C8: =IF(AND(C2>=FIRST_CLOSING_M,C2<FIRST_CLOSING_M+CLOSINGS_SPAN_M),ROUNDDOWN(UNITS_PH/CLOSINGS_SPAN_M,0)+IF(C2-FIRST_CLOSING_M+1<=UNITS_PH-ROUNDDOWN(UNITS_PH/CLOSINGS_SPAN_M,0)*CLOSINGS_SPAN_M,1,0),0) | D8: =IF(AND(D2>=FIRST_CLOSING_M,D2<FIRST_CLOSING_M+CLOSINGS_SPAN_M),ROUNDDOWN(UNITS_PH/CLOSINGS_SPAN_M,0)+IF(D2-FIRST_CLOSING_M+1<=UNITS_PH-ROUNDDOWN(UNITS_PH/CLOSINGS_SPAN_M,0)*CLOSINGS_SPAN_M,1,0),0) | E8: =IF(AND(E2>=FIRST_CLOSING_M,E2<FIRST_CLOSING_M+CLOSINGS_SPAN_M),ROUNDDOWN(UNITS_PH/CLOSINGS_SPAN_M,0)+IF(E2-FIRST_CLOSING_M+1<=UNITS_PH-ROUNDDOWN(UNITS_PH/CLOSINGS_SPAN_M,0)*CLOSINGS_SPAN_M,1,0),0) | F8: =IF(AND(F2>=FIRST_CLOSING_M,F2<FIRST_CLOSING_M+CLOSINGS_SPAN_M),ROUNDDOWN(UNITS_PH/CLOSINGS_SPAN_M,0)+IF(F2-FIRST_CLOSING_M+1<=UNITS_PH-ROUNDDOWN(UNITS_PH/CLOSINGS_SPAN_M,0)*CLOSINGS_SPAN_M,1,0),0) | G8: =IF(AND(G2>=FIRST_CLOSING_M,G2<FIRST_CLOSING_M+CLOSINGS_SPAN_M),ROUNDDOWN(UNITS_PH/CLOSINGS_SPAN_M,0)+IF(G2-FIRST_CLOSING_M+1<=UNITS_PH-ROUNDDOWN(UNITS_PH/CLOSINGS_SPAN_M,0)*CLOSINGS_SPAN_M,1,0),0) | H8: =IF(AND(H2>=FIRST_CLOSING_M,H2<FIRST_CLOSING_M+CLOSINGS_SPAN_M),ROUNDDOWN(UNITS_PH/CLOSINGS_SPAN_M,0)+IF(H2-FIRST_CLOSING_M+1<=UNITS_PH-ROUNDDOWN(UNITS_PH/CLOSINGS_SPAN_M,0)*CLOSINGS_SPAN_M,1,0),0) | I8: =IF(AND(I2>=FIRST_CLOSING_M,I2<FIRST_CLOSING_M+CLOSINGS_SPAN_M),ROUNDDOWN(UNITS_PH/CLOSINGS_SPAN_M,0)+IF(I2-FIRST_CLOSING_M+1<=UNITS_PH-ROUNDDOWN(UNITS_PH/CLOSINGS_SPAN_M,0)*CLOSINGS_SPAN_M,1,0),0) | J8: =IF(AND(J2>=FIRST_CLOSING_M,J2<FIRST_CLOSING_M+CLOSINGS_SPAN_M),ROUNDDOWN(UNITS_PH/CLOSINGS_SPAN_M,0)+IF(J2-FIRST_CLOSING_M+1<=UNITS_PH-ROUNDDOWN(UNITS_PH/CLOSINGS_SPAN_M,0)*CLOSINGS_SPAN_M,1,0),0) | ... CH8: =IF(AND(CH2>=FIRST_CLOSING_M,CH2<FIRST_CLOSING_M+CLOSINGS_SPAN_M),ROUNDDOWN(UNITS_PH/CLOSINGS_SPAN_M,0)+IF(CH2-FIRST_CLOSING_M+1<=UNITS_PH-ROUNDDOWN(UNITS_PH/CLOSINGS_SPAN_M,0)*CLOSINGS_SPAN_M,1,0),0)
A9: Total unit closings | B9: units | C9: =C4+C5+C6+C7+C8 | D9: =D4+D5+D6+D7+D8 | E9: =E4+E5+E6+E7+E8 | F9: =F4+F5+F6+F7+F8 | G9: =G4+G5+G6+G7+G8 | H9: =H4+H5+H6+H7+H8 | I9: =I4+I5+I6+I7+I8 | J9: =J4+J5+J6+J7+J8 | ... CH9: =CH4+CH5+CH6+CH7+CH8
A10: Unit revenue | B10: $ | C10: =C4*SQFT_STUDIO*PPSF_STUDIO+C5*SQFT_1BR*PPSF_1BR+C6*SQFT_2BR*PPSF_2BR+C7*SQFT_3BR*PPSF_3BR+C8*SQFT_PH*PPSF_PH | D10: =D4*SQFT_STUDIO*PPSF_STUDIO+D5*SQFT_1BR*PPSF_1BR+D6*SQFT_2BR*PPSF_2BR+D7*SQFT_3BR*PPSF_3BR+D8*SQFT_PH*PPSF_PH | E10: =E4*SQFT_STUDIO*PPSF_STUDIO+E5*SQFT_1BR*PPSF_1BR+E6*SQFT_2BR*PPSF_2BR+E7*SQFT_3BR*PPSF_3BR+E8*SQFT_PH*PPSF_PH | F10: =F4*SQFT_STUDIO*PPSF_STUDIO+F5*SQFT_1BR*PPSF_1BR+F6*SQFT_2BR*PPSF_2BR+F7*SQFT_3BR*PPSF_3BR+F8*SQFT_PH*PPSF_PH | G10: =G4*SQFT_STUDIO*PPSF_STUDIO+G5*SQFT_1BR*PPSF_1BR+G6*SQFT_2BR*PPSF_2BR+G7*SQFT_3BR*PPSF_3BR+G8*SQFT_PH*PPSF_PH | H10: =H4*SQFT_STUDIO*PPSF_STUDIO+H5*SQFT_1BR*PPSF_1BR+H6*SQFT_2BR*PPSF_2BR+H7*SQFT_3BR*PPSF_3BR+H8*SQFT_PH*PPSF_PH | I10: =I4*SQFT_STUDIO*PPSF_STUDIO+I5*SQFT_1BR*PPSF_1BR+I6*SQFT_2BR*PPSF_2BR+I7*SQFT_3BR*PPSF_3BR+I8*SQFT_PH*PPSF_PH | J10: =J4*SQFT_STUDIO*PPSF_STUDIO+J5*SQFT_1BR*PPSF_1BR+J6*SQFT_2BR*PPSF_2BR+J7*SQFT_3BR*PPSF_3BR+J8*SQFT_PH*PPSF_PH | ... CH10: =CH4*SQFT_STUDIO*PPSF_STUDIO+CH5*SQFT_1BR*PPSF_1BR+CH6*SQFT_2BR*PPSF_2BR+CH7*SQFT_3BR*PPSF_3BR+CH8*SQFT_PH*PPSF_PH
A11: Parking spaces released | B11: spaces | C11: =PARKING_SPACES*C9/(UNITS_STUDIO+UNITS_1BR+UNITS_2BR+UNITS_3BR+UNITS_PH) | D11: =PARKING_SPACES*D9/(UNITS_STUDIO+UNITS_1BR+UNITS_2BR+UNITS_3BR+UNITS_PH) | E11: =PARKING_SPACES*E9/(UNITS_STUDIO+UNITS_1BR+UNITS_2BR+UNITS_3BR+UNITS_PH) | F11: =PARKING_SPACES*F9/(UNITS_STUDIO+UNITS_1BR+UNITS_2BR+UNITS_3BR+UNITS_PH) | G11: =PARKING_SPACES*G9/(UNITS_STUDIO+UNITS_1BR+UNITS_2BR+UNITS_3BR+UNITS_PH) | H11: =PARKING_SPACES*H9/(UNITS_STUDIO+UNITS_1BR+UNITS_2BR+UNITS_3BR+UNITS_PH) | I11: =PARKING_SPACES*I9/(UNITS_STUDIO+UNITS_1BR+UNITS_2BR+UNITS_3BR+UNITS_PH) | J11: =PARKING_SPACES*J9/(UNITS_STUDIO+UNITS_1BR+UNITS_2BR+UNITS_3BR+UNITS_PH) | ... CH11: =PARKING_SPACES*CH9/(UNITS_STUDIO+UNITS_1BR+UNITS_2BR+UNITS_3BR+UNITS_PH)
A12: Storage units released | B12: units | C12: =STORAGE_UNITS*C9/(UNITS_STUDIO+UNITS_1BR+UNITS_2BR+UNITS_3BR+UNITS_PH) | D12: =STORAGE_UNITS*D9/(UNITS_STUDIO+UNITS_1BR+UNITS_2BR+UNITS_3BR+UNITS_PH) | E12: =STORAGE_UNITS*E9/(UNITS_STUDIO+UNITS_1BR+UNITS_2BR+UNITS_3BR+UNITS_PH) | F12: =STORAGE_UNITS*F9/(UNITS_STUDIO+UNITS_1BR+UNITS_2BR+UNITS_3BR+UNITS_PH) | G12: =STORAGE_UNITS*G9/(UNITS_STUDIO+UNITS_1BR+UNITS_2BR+UNITS_3BR+UNITS_PH) | H12: =STORAGE_UNITS*H9/(UNITS_STUDIO+UNITS_1BR+UNITS_2BR+UNITS_3BR+UNITS_PH) | I12: =STORAGE_UNITS*I9/(UNITS_STUDIO+UNITS_1BR+UNITS_2BR+UNITS_3BR+UNITS_PH) | J12: =STORAGE_UNITS*J9/(UNITS_STUDIO+UNITS_1BR+UNITS_2BR+UNITS_3BR+UNITS_PH) | ... CH12: =STORAGE_UNITS*CH9/(UNITS_STUDIO+UNITS_1BR+UNITS_2BR+UNITS_3BR+UNITS_PH)
A13: Parking revenue | B13: $ | C13: =C11*PARKING_PRICE | D13: =D11*PARKING_PRICE | E13: =E11*PARKING_PRICE | F13: =F11*PARKING_PRICE | G13: =G11*PARKING_PRICE | H13: =H11*PARKING_PRICE | I13: =I11*PARKING_PRICE | J13: =J11*PARKING_PRICE | ... CH13: =CH11*PARKING_PRICE
A14: Storage revenue | B14: $ | C14: =C12*STORAGE_PRICE | D14: =D12*STORAGE_PRICE | E14: =E12*STORAGE_PRICE | F14: =F12*STORAGE_PRICE | G14: =G12*STORAGE_PRICE | H14: =H12*STORAGE_PRICE | I14: =I12*STORAGE_PRICE | J14: =J12*STORAGE_PRICE | ... CH14: =CH12*STORAGE_PRICE
A15: Gross revenue | B15: $ | C15: =C10+C13+C14 | D15: =D10+D13+D14 | E15: =E10+E13+E14 | F15: =F10+F13+F14 | G15: =G10+G13+G14 | H15: =H10+H13+H14 | I15: =I10+I13+I14 | J15: =J10+J13+J14 | ... CH15: =CH10+CH13+CH14
A16: Net revenue | B16: $ | C16: =C15*(1-CLOSING_COST_PCT-MARKETING_PCT) | D16: =D15*(1-CLOSING_COST_PCT-MARKETING_PCT) | E16: =E15*(1-CLOSING_COST_PCT-MARKETING_PCT) | F16: =F15*(1-CLOSING_COST_PCT-MARKETING_PCT) | G16: =G15*(1-CLOSING_COST_PCT-MARKETING_PCT) | H16: =H15*(1-CLOSING_COST_PCT-MARKETING_PCT) | I16: =I15*(1-CLOSING_COST_PCT-MARKETING_PCT) | J16: =J15*(1-CLOSING_COST_PCT-MARKETING_PCT) | ... CH16: =CH15*(1-CLOSING_COST_PCT-MARKETING_PCT)

Sheet RetailProForma
A1: RetailProForma
A2: Month | B2: index | C2: =COLUMN()-2 | D2: =COLUMN()-2 | E2: =COLUMN()-2 | F2: =COLUMN()-2 | G2: =COLUMN()-2 | H2: =COLUMN()-2 | I2: =COLUMN()-2 | J2: =COLUMN()-2 | ... CH2: =COLUMN()-2
A3: Date | B3: month-end | C3: =EOMONTH(DATE(2026,1,1),C2-1) | D3: =EOMONTH(DATE(2026,1,1),D2-1) | E3: =EOMONTH(DATE(2026,1,1),E2-1) | F3: =EOMONTH(DATE(2026,1,1),F2-1) | G3: =EOMONTH(DATE(2026,1,1),G2-1) | H3: =EOMONTH(DATE(2026,1,1),H2-1) | I3: =EOMONTH(DATE(2026,1,1),I2-1) | J3: =EOMONTH(DATE(2026,1,1),J2-1) | ... CH3: =EOMONTH(DATE(2026,1,1),CH2-1)
A4: Operating | B4: 1/0 | C4: =IF(C2>=RETAIL_OPEN_M,1,0) | D4: =IF(D2>=RETAIL_OPEN_M,1,0) | E4: =IF(E2>=RETAIL_OPEN_M,1,0) | F4: =IF(F2>=RETAIL_OPEN_M,1,0) | G4: =IF(G2>=RETAIL_OPEN_M,1,0) | H4: =IF(H2>=RETAIL_OPEN_M,1,0) | I4: =IF(I2>=RETAIL_OPEN_M,1,0) | J4: =IF(J2>=RETAIL_OPEN_M,1,0) | ... CH4: =IF(CH2>=RETAIL_OPEN_M,1,0)
A5: Months from open | B5: months | C5: =IF(C4=1,C2-RETAIL_OPEN_M,0) | D5: =IF(D4=1,D2-RETAIL_OPEN_M,0) | E5: =IF(E4=1,E2-RETAIL_OPEN_M,0) | F5: =IF(F4=1,F2-RETAIL_OPEN_M,0) | G5: =IF(G4=1,G2-RETAIL_OPEN_M,0) | H5: =IF(H4=1,H2-RETAIL_OPEN_M,0) | I5: =IF(I4=1,I2-RETAIL_OPEN_M,0) | J5: =IF(J4=1,J2-RETAIL_OPEN_M,0) | ... CH5: =IF(CH4=1,CH2-RETAIL_OPEN_M,0)
A6: Escalation year index | B6: year | C6: =IF(C4=1,INT(C5/12),0) | D6: =IF(D4=1,INT(D5/12),0) | E6: =IF(E4=1,INT(E5/12),0) | F6: =IF(F4=1,INT(F5/12),0) | G6: =IF(G4=1,INT(G5/12),0) | H6: =IF(H4=1,INT(H5/12),0) | I6: =IF(I4=1,INT(I5/12),0) | J6: =IF(J4=1,INT(J5/12),0) | ... CH6: =IF(CH4=1,INT(CH5/12),0)
A7: Base rent | B7: $ | C7: =IF(C4=1,RETAIL_BASE_PSF*(1+RETAIL_ESC_PCT)^C6*RETAIL_GSF/12,0) | D7: =IF(D4=1,RETAIL_BASE_PSF*(1+RETAIL_ESC_PCT)^D6*RETAIL_GSF/12,0) | E7: =IF(E4=1,RETAIL_BASE_PSF*(1+RETAIL_ESC_PCT)^E6*RETAIL_GSF/12,0) | F7: =IF(F4=1,RETAIL_BASE_PSF*(1+RETAIL_ESC_PCT)^F6*RETAIL_GSF/12,0) | G7: =IF(G4=1,RETAIL_BASE_PSF*(1+RETAIL_ESC_PCT)^G6*RETAIL_GSF/12,0) | H7: =IF(H4=1,RETAIL_BASE_PSF*(1+RETAIL_ESC_PCT)^H6*RETAIL_GSF/12,0) | I7: =IF(I4=1,RETAIL_BASE_PSF*(1+RETAIL_ESC_PCT)^I6*RETAIL_GSF/12,0) | J7: =IF(J4=1,RETAIL_BASE_PSF*(1+RETAIL_ESC_PCT)^J6*RETAIL_GSF/12,0) | ... CH7: =IF(CH4=1,RETAIL_BASE_PSF*(1+RETAIL_ESC_PCT)^CH6*RETAIL_GSF/12,0)
A8: Recovery income | B8: $ | C8: =IF(C4=1,RETAIL_RECOV_PSF*(1+RETAIL_ESC_PCT)^C6*RETAIL_GSF*RETAIL_RECOV_RATIO/12,0) | D8: =IF(D4=1,RETAIL_RECOV_PSF*(1+RETAIL_ESC_PCT)^D6*RETAIL_GSF*RETAIL_RECOV_RATIO/12,0) | E8: =IF(E4=1,RETAIL_RECOV_PSF*(1+RETAIL_ESC_PCT)^E6*RETAIL_GSF*RETAIL_RECOV_RATIO/12,0) | F8: =IF(F4=1,RETAIL_RECOV_PSF*(1+RETAIL_ESC_PCT)^F6*RETAIL_GSF*RETAIL_RECOV_RATIO/12,0) | G8: =IF(G4=1,RETAIL_RECOV_PSF*(1+RETAIL_ESC_PCT)^G6*RETAIL_GSF*RETAIL_RECOV_RATIO/12,0) | H8: =IF(H4=1,RETAIL_RECOV_PSF*(1+RETAIL_ESC_PCT)^H6*RETAIL_GSF*RETAIL_RECOV_RATIO/12,0) | I8: =IF(I4=1,RETAIL_RECOV_PSF*(1+RETAIL_ESC_PCT)^I6*RETAIL_GSF*RETAIL_RECOV_RATIO/12,0) | J8: =IF(J4=1,RETAIL_RECOV_PSF*(1+RETAIL_ESC_PCT)^J6*RETAIL_GSF*RETAIL_RECOV_RATIO/12,0) | ... CH8: =IF(CH4=1,RETAIL_RECOV_PSF*(1+RETAIL_ESC_PCT)^CH6*RETAIL_GSF*RETAIL_RECOV_RATIO/12,0)
A9: EGI | B9: $ | C9: =IF(C4=1,(C7+C8)*(1-RETAIL_VAC_PCT),0) | D9: =IF(D4=1,(D7+D8)*(1-RETAIL_VAC_PCT),0) | E9: =IF(E4=1,(E7+E8)*(1-RETAIL_VAC_PCT),0) | F9: =IF(F4=1,(F7+F8)*(1-RETAIL_VAC_PCT),0) | G9: =IF(G4=1,(G7+G8)*(1-RETAIL_VAC_PCT),0) | H9: =IF(H4=1,(H7+H8)*(1-RETAIL_VAC_PCT),0) | I9: =IF(I4=1,(I7+I8)*(1-RETAIL_VAC_PCT),0) | J9: =IF(J4=1,(J7+J8)*(1-RETAIL_VAC_PCT),0) | ... CH9: =IF(CH4=1,(CH7+CH8)*(1-RETAIL_VAC_PCT),0)
A10: Non-recoverable opex | B10: $ | C10: =IF(C4=1,RETAIL_OP_PSF*RETAIL_GSF/12,0) | D10: =IF(D4=1,RETAIL_OP_PSF*RETAIL_GSF/12,0) | E10: =IF(E4=1,RETAIL_OP_PSF*RETAIL_GSF/12,0) | F10: =IF(F4=1,RETAIL_OP_PSF*RETAIL_GSF/12,0) | G10: =IF(G4=1,RETAIL_OP_PSF*RETAIL_GSF/12,0) | H10: =IF(H4=1,RETAIL_OP_PSF*RETAIL_GSF/12,0) | I10: =IF(I4=1,RETAIL_OP_PSF*RETAIL_GSF/12,0) | J10: =IF(J4=1,RETAIL_OP_PSF*RETAIL_GSF/12,0) | ... CH10: =IF(CH4=1,RETAIL_OP_PSF*RETAIL_GSF/12,0)
A11: Management fee | B11: $ | C11: =RETAIL_MGMT_PCT*C9 | D11: =RETAIL_MGMT_PCT*D9 | E11: =RETAIL_MGMT_PCT*E9 | F11: =RETAIL_MGMT_PCT*F9 | G11: =RETAIL_MGMT_PCT*G9 | H11: =RETAIL_MGMT_PCT*H9 | I11: =RETAIL_MGMT_PCT*I9 | J11: =RETAIL_MGMT_PCT*J9 | ... CH11: =RETAIL_MGMT_PCT*CH9
A12: Retail NOI | B12: $ | C12: =C9-C10-C11 | D12: =D9-D10-D11 | E12: =E9-E10-E11 | F12: =F9-F10-F11 | G12: =G9-G10-G11 | H12: =H9-H10-H11 | I12: =I9-I10-I11 | J12: =J9-J10-J11 | ... CH12: =CH9-CH10-CH11

Sheet HotelProForma
A1: HotelProForma
A2: Month | B2: index | C2: =COLUMN()-2 | D2: =COLUMN()-2 | E2: =COLUMN()-2 | F2: =COLUMN()-2 | G2: =COLUMN()-2 | H2: =COLUMN()-2 | I2: =COLUMN()-2 | J2: =COLUMN()-2 | ... CH2: =COLUMN()-2
A3: Date | B3: month-end | C3: =EOMONTH(DATE(2026,1,1),C2-1) | D3: =EOMONTH(DATE(2026,1,1),D2-1) | E3: =EOMONTH(DATE(2026,1,1),E2-1) | F3: =EOMONTH(DATE(2026,1,1),F2-1) | G3: =EOMONTH(DATE(2026,1,1),G2-1) | H3: =EOMONTH(DATE(2026,1,1),H2-1) | I3: =EOMONTH(DATE(2026,1,1),I2-1) | J3: =EOMONTH(DATE(2026,1,1),J2-1) | ... CH3: =EOMONTH(DATE(2026,1,1),CH2-1)
A4: Operating | B4: 1/0 | C4: =IF(C2>=HOTEL_OPEN_M,1,0) | D4: =IF(D2>=HOTEL_OPEN_M,1,0) | E4: =IF(E2>=HOTEL_OPEN_M,1,0) | F4: =IF(F2>=HOTEL_OPEN_M,1,0) | G4: =IF(G2>=HOTEL_OPEN_M,1,0) | H4: =IF(H2>=HOTEL_OPEN_M,1,0) | I4: =IF(I2>=HOTEL_OPEN_M,1,0) | J4: =IF(J2>=HOTEL_OPEN_M,1,0) | ... CH4: =IF(CH2>=HOTEL_OPEN_M,1,0)
A5: Operating year | B5: year | C5: =IF(C4=1,INT((C2-HOTEL_OPEN_M)/12)+1,0) | D5: =IF(D4=1,INT((D2-HOTEL_OPEN_M)/12)+1,0) | E5: =IF(E4=1,INT((E2-HOTEL_OPEN_M)/12)+1,0) | F5: =IF(F4=1,INT((F2-HOTEL_OPEN_M)/12)+1,0) | G5: =IF(G4=1,INT((G2-HOTEL_OPEN_M)/12)+1,0) | H5: =IF(H4=1,INT((H2-HOTEL_OPEN_M)/12)+1,0) | I5: =IF(I4=1,INT((I2-HOTEL_OPEN_M)/12)+1,0) | J5: =IF(J4=1,INT((J2-HOTEL_OPEN_M)/12)+1,0) | ... CH5: =IF(CH4=1,INT((CH2-HOTEL_OPEN_M)/12)+1,0)
A6: ADR | B6: $ | C6: =IF(C4=1,ADR_Y1*(1+ADR_GROWTH_PCT)^(C5-1),0) | D6: =IF(D4=1,ADR_Y1*(1+ADR_GROWTH_PCT)^(D5-1),0) | E6: =IF(E4=1,ADR_Y1*(1+ADR_GROWTH_PCT)^(E5-1),0) | F6: =IF(F4=1,ADR_Y1*(1+ADR_GROWTH_PCT)^(F5-1),0) | G6: =IF(G4=1,ADR_Y1*(1+ADR_GROWTH_PCT)^(G5-1),0) | H6: =IF(H4=1,ADR_Y1*(1+ADR_GROWTH_PCT)^(H5-1),0) | I6: =IF(I4=1,ADR_Y1*(1+ADR_GROWTH_PCT)^(I5-1),0) | J6: =IF(J4=1,ADR_Y1*(1+ADR_GROWTH_PCT)^(J5-1),0) | ... CH6: =IF(CH4=1,ADR_Y1*(1+ADR_GROWTH_PCT)^(CH5-1),0)
A7: Occupancy | B7: % | C7: =IF(C4=1,IF(C5<=1,OCC_Y1,IF(C5=2,OCC_Y2,OCC_STAB)),0) | D7: =IF(D4=1,IF(D5<=1,OCC_Y1,IF(D5=2,OCC_Y2,OCC_STAB)),0) | E7: =IF(E4=1,IF(E5<=1,OCC_Y1,IF(E5=2,OCC_Y2,OCC_STAB)),0) | F7: =IF(F4=1,IF(F5<=1,OCC_Y1,IF(F5=2,OCC_Y2,OCC_STAB)),0) | G7: =IF(G4=1,IF(G5<=1,OCC_Y1,IF(G5=2,OCC_Y2,OCC_STAB)),0) | H7: =IF(H4=1,IF(H5<=1,OCC_Y1,IF(H5=2,OCC_Y2,OCC_STAB)),0) | I7: =IF(I4=1,IF(I5<=1,OCC_Y1,IF(I5=2,OCC_Y2,OCC_STAB)),0) | J7: =IF(J4=1,IF(J5<=1,OCC_Y1,IF(J5=2,OCC_Y2,OCC_STAB)),0) | ... CH7: =IF(CH4=1,IF(CH5<=1,OCC_Y1,IF(CH5=2,OCC_Y2,OCC_STAB)),0)
A8: Days | B8: days | C8: =IF(C4=1,DAY(C3),0) | D8: =IF(D4=1,DAY(D3),0) | E8: =IF(E4=1,DAY(E3),0) | F8: =IF(F4=1,DAY(F3),0) | G8: =IF(G4=1,DAY(G3),0) | H8: =IF(H4=1,DAY(H3),0) | I8: =IF(I4=1,DAY(I3),0) | J8: =IF(J4=1,DAY(J3),0) | ... CH8: =IF(CH4=1,DAY(CH3),0)
A9: Rooms revenue | B9: $ | C9: =IF(C4=1,HOTEL_KEYS*C8*C7*C6,0) | D9: =IF(D4=1,HOTEL_KEYS*D8*D7*D6,0) | E9: =IF(E4=1,HOTEL_KEYS*E8*E7*E6,0) | F9: =IF(F4=1,HOTEL_KEYS*F8*F7*F6,0) | G9: =IF(G4=1,HOTEL_KEYS*G8*G7*G6,0) | H9: =IF(H4=1,HOTEL_KEYS*H8*H7*H6,0) | I9: =IF(I4=1,HOTEL_KEYS*I8*I7*I6,0) | J9: =IF(J4=1,HOTEL_KEYS*J8*J7*J6,0) | ... CH9: =IF(CH4=1,HOTEL_KEYS*CH8*CH7*CH6,0)
A10: Total revenue | B10: $ | C10: =C9*(1+FB_REV_PCT+OTHER_REV_PCT) | D10: =D9*(1+FB_REV_PCT+OTHER_REV_PCT) | E10: =E9*(1+FB_REV_PCT+OTHER_REV_PCT) | F10: =F9*(1+FB_REV_PCT+OTHER_REV_PCT) | G10: =G9*(1+FB_REV_PCT+OTHER_REV_PCT) | H10: =H9*(1+FB_REV_PCT+OTHER_REV_PCT) | I10: =I9*(1+FB_REV_PCT+OTHER_REV_PCT) | J10: =J9*(1+FB_REV_PCT+OTHER_REV_PCT) | ... CH10: =CH9*(1+FB_REV_PCT+OTHER_REV_PCT)
A11: Hotel NOI | B11: $ | C11: =C10*(1-HOTEL_UNDIST_PCT-HOTEL_MGMT_PCT-REPL_RESERVE_PCT) | D11: =D10*(1-HOTEL_UNDIST_PCT-HOTEL_MGMT_PCT-REPL_RESERVE_PCT) | E11: =E10*(1-HOTEL_UNDIST_PCT-HOTEL_MGMT_PCT-REPL_RESERVE_PCT) | F11: =F10*(1-HOTEL_UNDIST_PCT-HOTEL_MGMT_PCT-REPL_RESERVE_PCT) | G11: =G10*(1-HOTEL_UNDIST_PCT-HOTEL_MGMT_PCT-REPL_RESERVE_PCT) | H11: =H10*(1-HOTEL_UNDIST_PCT-HOTEL_MGMT_PCT-REPL_RESERVE_PCT) | I11: =I10*(1-HOTEL_UNDIST_PCT-HOTEL_MGMT_PCT-REPL_RESERVE_PCT) | J11: =J10*(1-HOTEL_UNDIST_PCT-HOTEL_MGMT_PCT-REPL_RESERVE_PCT) | ... CH11: =CH10*(1-HOTEL_UNDIST_PCT-HOTEL_MGMT_PCT-REPL_RESERVE_PCT)

Sheet ConstructionDebt
A1: ConstructionDebt
A2: Month | B2: index | C2: =COLUMN()-2 | D2: =COLUMN()-2 | E2: =COLUMN()-2 | F2: =COLUMN()-2 | G2: =COLUMN()-2 | H2: =COLUMN()-2 | I2: =COLUMN()-2 | J2: =COLUMN()-2 | ... CH2: =COLUMN()-2
A3: Date | B3: month-end | C3: =EOMONTH(DATE(2026,1,1),C2-1) | D3: =EOMONTH(DATE(2026,1,1),D2-1) | E3: =EOMONTH(DATE(2026,1,1),E2-1) | F3: =EOMONTH(DATE(2026,1,1),F2-1) | G3: =EOMONTH(DATE(2026,1,1),G2-1) | H3: =EOMONTH(DATE(2026,1,1),H2-1) | I3: =EOMONTH(DATE(2026,1,1),I2-1) | J3: =EOMONTH(DATE(2026,1,1),J2-1) | ... CH3: =EOMONTH(DATE(2026,1,1),CH2-1)
A4: SOFR forward | B4: % | C4: =INDEX(SOFR!$C$2:$C$85,C2) | D4: =INDEX(SOFR!$C$2:$C$85,D2) | E4: =INDEX(SOFR!$C$2:$C$85,E2) | F4: =INDEX(SOFR!$C$2:$C$85,F2) | G4: =INDEX(SOFR!$C$2:$C$85,G2) | H4: =INDEX(SOFR!$C$2:$C$85,H2) | I4: =INDEX(SOFR!$C$2:$C$85,I2) | J4: =INDEX(SOFR!$C$2:$C$85,J2) | ... CH4: =INDEX(SOFR!$C$2:$C$85,CH2)
A5: All-in rate | B5: % | C5: =MAX(SOFR_FLOOR_PCT,C4)+CT_SPREAD_PCT | D5: =MAX(SOFR_FLOOR_PCT,D4)+CT_SPREAD_PCT | E5: =MAX(SOFR_FLOOR_PCT,E4)+CT_SPREAD_PCT | F5: =MAX(SOFR_FLOOR_PCT,F4)+CT_SPREAD_PCT | G5: =MAX(SOFR_FLOOR_PCT,G4)+CT_SPREAD_PCT | H5: =MAX(SOFR_FLOOR_PCT,H4)+CT_SPREAD_PCT | I5: =MAX(SOFR_FLOOR_PCT,I4)+CT_SPREAD_PCT | J5: =MAX(SOFR_FLOOR_PCT,J4)+CT_SPREAD_PCT | ... CH5: =MAX(SOFR_FLOOR_PCT,CH4)+CT_SPREAD_PCT
A6: Budget spend | B6: $ | C6: =SpendCurve!C10 | D6: =SpendCurve!D10 | E6: =SpendCurve!E10 | F6: =SpendCurve!F10 | G6: =SpendCurve!G10 | H6: =SpendCurve!H10 | I6: =SpendCurve!I10 | J6: =SpendCurve!J10 | ... CH6: =SpendCurve!CH10
A7: Equity cash opening | B7: $ | C7: =0 | D7: =C10 | E7: =D10 | F7: =E10 | G7: =F10 | H7: =G10 | I7: =H10 | J7: =I10 | K7: =J10 | ... CH7: =CG10
A8: Equity contribution | B8: $ | C8: =IF(C2=1,SourcesUses!$C$28,0) | D8: =IF(D2=1,SourcesUses!$C$28,0) | E8: =IF(E2=1,SourcesUses!$C$28,0) | F8: =IF(F2=1,SourcesUses!$C$28,0) | G8: =IF(G2=1,SourcesUses!$C$28,0) | H8: =IF(H2=1,SourcesUses!$C$28,0) | I8: =IF(I2=1,SourcesUses!$C$28,0) | J8: =IF(J2=1,SourcesUses!$C$28,0) | ... CH8: =IF(CH2=1,SourcesUses!$C$28,0)
A9: Equity used | B9: $ | C9: =MIN(C7+C8,C6) | D9: =MIN(D7+D8,D6) | E9: =MIN(E7+E8,E6) | F9: =MIN(F7+F8,F6) | G9: =MIN(G7+G8,G6) | H9: =MIN(H7+H8,H6) | I9: =MIN(I7+I8,I6) | J9: =MIN(J7+J8,J6) | ... CH9: =MIN(CH7+CH8,CH6)
A10: Equity cash closing | B10: $ | C10: =C7+C8-C9 | D10: =D7+D8-D9 | E10: =E7+E8-E9 | F10: =F7+F8-F9 | G10: =G7+G8-G9 | H10: =H7+H8-H9 | I10: =I7+I8-I9 | J10: =J7+J8-J9 | ... CH10: =CH7+CH8-CH9
A11: Draws for spend | B11: $ | C11: =C6-C9 | D11: =D6-D9 | E11: =E6-E9 | F11: =F6-F9 | G11: =G6-G9 | H11: =H6-H9 | I11: =I6-I9 | J11: =J6-J9 | ... CH11: =CH6-CH9
A12: Debt opening balance | B12: $ | C12: =0 | D12: =C21 | E12: =D21 | F12: =E21 | G12: =F21 | H12: =G21 | I12: =H21 | J12: =I21 | K12: =J21 | ... CH12: =CG21
A13: Interest on opening balance | B13: $ | C13: =C12*(MAX(SOFR_FLOOR_PCT,INDEX(SOFR!$C$2:$C$85,C2))+CT_SPREAD_PCT)/12 | D13: =D12*(MAX(SOFR_FLOOR_PCT,INDEX(SOFR!$C$2:$C$85,D2))+CT_SPREAD_PCT)/12 | E13: =E12*(MAX(SOFR_FLOOR_PCT,INDEX(SOFR!$C$2:$C$85,E2))+CT_SPREAD_PCT)/12 | F13: =F12*(MAX(SOFR_FLOOR_PCT,INDEX(SOFR!$C$2:$C$85,F2))+CT_SPREAD_PCT)/12 | G13: =G12*(MAX(SOFR_FLOOR_PCT,INDEX(SOFR!$C$2:$C$85,G2))+CT_SPREAD_PCT)/12 | H13: =H12*(MAX(SOFR_FLOOR_PCT,INDEX(SOFR!$C$2:$C$85,H2))+CT_SPREAD_PCT)/12 | I13: =I12*(MAX(SOFR_FLOOR_PCT,INDEX(SOFR!$C$2:$C$85,I2))+CT_SPREAD_PCT)/12 | J13: =J12*(MAX(SOFR_FLOOR_PCT,INDEX(SOFR!$C$2:$C$85,J2))+CT_SPREAD_PCT)/12 | ... CH13: =CH12*(MAX(SOFR_FLOOR_PCT,INDEX(SOFR!$C$2:$C$85,CH2))+CT_SPREAD_PCT)/12
A14: Capitalized interest draw | B14: $ | C14: =C13 | D14: =D13 | E14: =E13 | F14: =F13 | G14: =G13 | H14: =H13 | I14: =I13 | J14: =J13 | ... CH14: =CH13
A15: Total draws | B15: $ | C15: =C11+C14 | D15: =D11+D14 | E15: =E11+E14 | F15: =F11+F14 | G15: =G11+G14 | H15: =H11+H14 | I15: =I11+I14 | J15: =J11+J14 | ... CH15: =CH11+CH14
A16: Balance after draws | B16: $ | C16: =C12+C15 | D16: =D12+D15 | E16: =E12+E15 | F16: =F12+F15 | G16: =G12+G15 | H16: =H12+H15 | I16: =I12+I15 | J16: =J12+J15 | ... CH16: =CH12+CH15
A17: Condo net revenue | B17: $ | C17: =CondoSellout!C16 | D17: =CondoSellout!D16 | E17: =CondoSellout!E16 | F17: =CondoSellout!F16 | G17: =CondoSellout!G16 | H17: =CondoSellout!H16 | I17: =CondoSellout!I16 | J17: =CondoSellout!J16 | ... CH17: =CondoSellout!CH16
A18: Condo repayment | B18: $ | C18: =MIN(C16,MAX(C17,0)) | D18: =MIN(D16,MAX(D17,0)) | E18: =MIN(E16,MAX(E17,0)) | F18: =MIN(F16,MAX(F17,0)) | G18: =MIN(G16,MAX(G17,0)) | H18: =MIN(H16,MAX(H17,0)) | I18: =MIN(I16,MAX(I17,0)) | J18: =MIN(J16,MAX(J17,0)) | ... CH18: =MIN(CH16,MAX(CH17,0))
A19: Permanent-loan payoff of construction balance | B19: $ | C19: =IF(C2=PERM_CONV_M,MAX(0,C16-C18),0) | D19: =IF(D2=PERM_CONV_M,MAX(0,D16-D18),0) | E19: =IF(E2=PERM_CONV_M,MAX(0,E16-E18),0) | F19: =IF(F2=PERM_CONV_M,MAX(0,F16-F18),0) | G19: =IF(G2=PERM_CONV_M,MAX(0,G16-G18),0) | H19: =IF(H2=PERM_CONV_M,MAX(0,H16-H18),0) | I19: =IF(I2=PERM_CONV_M,MAX(0,I16-I18),0) | J19: =IF(J2=PERM_CONV_M,MAX(0,J16-J18),0) | ... CH19: =IF(CH2=PERM_CONV_M,MAX(0,CH16-CH18),0)
A20: Total repayments | B20: $ | C20: =C18+C19 | D20: =D18+D19 | E20: =E18+E19 | F20: =F18+F19 | G20: =G18+G19 | H20: =H18+H19 | I20: =I18+I19 | J20: =J18+J19 | ... CH20: =CH18+CH19
A21: Debt closing balance | B21: $ | C21: =C12+C15-C20 | D21: =D12+D15-D20 | E21: =E12+E15-E20 | F21: =F12+F15-F20 | G21: =G12+G15-G20 | H21: =H12+H15-H20 | I21: =I12+I15-I20 | J21: =J12+J15-J20 | ... CH21: =CH12+CH15-CH20
A23: Audit interest gap | B23: $ | C23: =ABS(C13-C12*(MAX(SOFR_FLOOR_PCT,INDEX(SOFR!$C$2:$C$85,C2))+CT_SPREAD_PCT)/12) | D23: =ABS(D13-D12*(MAX(SOFR_FLOOR_PCT,INDEX(SOFR!$C$2:$C$85,D2))+CT_SPREAD_PCT)/12) | E23: =ABS(E13-E12*(MAX(SOFR_FLOOR_PCT,INDEX(SOFR!$C$2:$C$85,E2))+CT_SPREAD_PCT)/12) | F23: =ABS(F13-F12*(MAX(SOFR_FLOOR_PCT,INDEX(SOFR!$C$2:$C$85,F2))+CT_SPREAD_PCT)/12) | G23: =ABS(G13-G12*(MAX(SOFR_FLOOR_PCT,INDEX(SOFR!$C$2:$C$85,G2))+CT_SPREAD_PCT)/12) | H23: =ABS(H13-H12*(MAX(SOFR_FLOOR_PCT,INDEX(SOFR!$C$2:$C$85,H2))+CT_SPREAD_PCT)/12) | I23: =ABS(I13-I12*(MAX(SOFR_FLOOR_PCT,INDEX(SOFR!$C$2:$C$85,I2))+CT_SPREAD_PCT)/12) | J23: =ABS(J13-J12*(MAX(SOFR_FLOOR_PCT,INDEX(SOFR!$C$2:$C$85,J2))+CT_SPREAD_PCT)/12) | ... CH23: =ABS(CH13-CH12*(MAX(SOFR_FLOOR_PCT,INDEX(SOFR!$C$2:$C$85,CH2))+CT_SPREAD_PCT)/12)
A24: Audit roll-forward gap | B24: $ | C24: =ABS(C12-0) | D24: =ABS(D12-(C12+C15-C20)) | E24: =ABS(E12-(D12+D15-D20)) | F24: =ABS(F12-(E12+E15-E20)) | G24: =ABS(G12-(F12+F15-F20)) | H24: =ABS(H12-(G12+G15-G20)) | I24: =ABS(I12-(H12+H15-H20)) | J24: =ABS(J12-(I12+I15-I20)) | K24: =ABS(K12-(J12+J15-J20)) | ... CH24: =ABS(CH12-(CG12+CG15-CG20))

Sheet PermanentDebt
A1: PermanentDebt
A2: Month | B2: index | C2: =COLUMN()-2 | D2: =COLUMN()-2 | E2: =COLUMN()-2 | F2: =COLUMN()-2 | G2: =COLUMN()-2 | H2: =COLUMN()-2 | I2: =COLUMN()-2 | J2: =COLUMN()-2 | ... CH2: =COLUMN()-2
A3: Date | B3: month-end | C3: =EOMONTH(DATE(2026,1,1),C2-1) | D3: =EOMONTH(DATE(2026,1,1),D2-1) | E3: =EOMONTH(DATE(2026,1,1),E2-1) | F3: =EOMONTH(DATE(2026,1,1),F2-1) | G3: =EOMONTH(DATE(2026,1,1),G2-1) | H3: =EOMONTH(DATE(2026,1,1),H2-1) | I3: =EOMONTH(DATE(2026,1,1),I2-1) | J3: =EOMONTH(DATE(2026,1,1),J2-1) | ... CH3: =EOMONTH(DATE(2026,1,1),CH2-1)
A4: Permanent loan active | B4: 1/0 | C4: =IF(AND(C2>=PERM_CONV_M,C2<=EXIT_M),1,0) | D4: =IF(AND(D2>=PERM_CONV_M,D2<=EXIT_M),1,0) | E4: =IF(AND(E2>=PERM_CONV_M,E2<=EXIT_M),1,0) | F4: =IF(AND(F2>=PERM_CONV_M,F2<=EXIT_M),1,0) | G4: =IF(AND(G2>=PERM_CONV_M,G2<=EXIT_M),1,0) | H4: =IF(AND(H2>=PERM_CONV_M,H2<=EXIT_M),1,0) | I4: =IF(AND(I2>=PERM_CONV_M,I2<=EXIT_M),1,0) | J4: =IF(AND(J2>=PERM_CONV_M,J2<=EXIT_M),1,0) | ... CH4: =IF(AND(CH2>=PERM_CONV_M,CH2<=EXIT_M),1,0)
A5: Opening balance | B5: $ | C5: =IF(C2<PERM_CONV_M,0,IF(C2=PERM_CONV_M,$C$39,0)) | D5: =IF(D2<PERM_CONV_M,0,IF(D2=PERM_CONV_M,$C$39,C12)) | E5: =IF(E2<PERM_CONV_M,0,IF(E2=PERM_CONV_M,$C$39,D12)) | F5: =IF(F2<PERM_CONV_M,0,IF(F2=PERM_CONV_M,$C$39,E12)) | G5: =IF(G2<PERM_CONV_M,0,IF(G2=PERM_CONV_M,$C$39,F12)) | H5: =IF(H2<PERM_CONV_M,0,IF(H2=PERM_CONV_M,$C$39,G12)) | I5: =IF(I2<PERM_CONV_M,0,IF(I2=PERM_CONV_M,$C$39,H12)) | J5: =IF(J2<PERM_CONV_M,0,IF(J2=PERM_CONV_M,$C$39,I12)) | K5: =IF(K2<PERM_CONV_M,0,IF(K2=PERM_CONV_M,$C$39,J12)) | ... CH5: =IF(CH2<PERM_CONV_M,0,IF(CH2=PERM_CONV_M,$C$39,CG12))
A6: Interest on opening balance | B6: $ | C6: =C5*PERM_RATE_PCT/12 | D6: =D5*PERM_RATE_PCT/12 | E6: =E5*PERM_RATE_PCT/12 | F6: =F5*PERM_RATE_PCT/12 | G6: =G5*PERM_RATE_PCT/12 | H6: =H5*PERM_RATE_PCT/12 | I6: =I5*PERM_RATE_PCT/12 | J6: =J5*PERM_RATE_PCT/12 | ... CH6: =CH5*PERM_RATE_PCT/12
A7: Scheduled payment | B7: $ | C7: =IF(AND(C2>=PERM_CONV_M,C2<EXIT_M),PMT(PERM_RATE_PCT/12,PERM_AMORT_YRS*12,-$C$39),0) | D7: =IF(AND(D2>=PERM_CONV_M,D2<EXIT_M),PMT(PERM_RATE_PCT/12,PERM_AMORT_YRS*12,-$C$39),0) | E7: =IF(AND(E2>=PERM_CONV_M,E2<EXIT_M),PMT(PERM_RATE_PCT/12,PERM_AMORT_YRS*12,-$C$39),0) | F7: =IF(AND(F2>=PERM_CONV_M,F2<EXIT_M),PMT(PERM_RATE_PCT/12,PERM_AMORT_YRS*12,-$C$39),0) | G7: =IF(AND(G2>=PERM_CONV_M,G2<EXIT_M),PMT(PERM_RATE_PCT/12,PERM_AMORT_YRS*12,-$C$39),0) | H7: =IF(AND(H2>=PERM_CONV_M,H2<EXIT_M),PMT(PERM_RATE_PCT/12,PERM_AMORT_YRS*12,-$C$39),0) | I7: =IF(AND(I2>=PERM_CONV_M,I2<EXIT_M),PMT(PERM_RATE_PCT/12,PERM_AMORT_YRS*12,-$C$39),0) | J7: =IF(AND(J2>=PERM_CONV_M,J2<EXIT_M),PMT(PERM_RATE_PCT/12,PERM_AMORT_YRS*12,-$C$39),0) | ... CH7: =IF(AND(CH2>=PERM_CONV_M,CH2<EXIT_M),PMT(PERM_RATE_PCT/12,PERM_AMORT_YRS*12,-$C$39),0)
A8: Scheduled principal | B8: $ | C8: =IF(C7=0,0,C7-C6) | D8: =IF(D7=0,0,D7-D6) | E8: =IF(E7=0,0,E7-E6) | F8: =IF(F7=0,0,F7-F6) | G8: =IF(G7=0,0,G7-G6) | H8: =IF(H7=0,0,H7-H6) | I8: =IF(I7=0,0,I7-I6) | J8: =IF(J7=0,0,J7-J6) | ... CH8: =IF(CH7=0,0,CH7-CH6)
A9: Exit payoff | B9: $ | C9: =IF(C2=EXIT_M,C5,0) | D9: =IF(D2=EXIT_M,D5,0) | E9: =IF(E2=EXIT_M,E5,0) | F9: =IF(F2=EXIT_M,F5,0) | G9: =IF(G2=EXIT_M,G5,0) | H9: =IF(H2=EXIT_M,H5,0) | I9: =IF(I2=EXIT_M,I5,0) | J9: =IF(J2=EXIT_M,J5,0) | ... CH9: =IF(CH2=EXIT_M,CH5,0)
A10: Debt service excluding balloon | B10: $ | C10: =C6+C8 | D10: =D6+D8 | E10: =E6+E8 | F10: =F6+F8 | G10: =G6+G8 | H10: =H6+H8 | I10: =I6+I8 | J10: =J6+J8 | ... CH10: =CH6+CH8
A11: Construction balance repaid | B11: $ | C11: =ConstructionDebt!C19 | D11: =ConstructionDebt!D19 | E11: =ConstructionDebt!E19 | F11: =ConstructionDebt!F19 | G11: =ConstructionDebt!G19 | H11: =ConstructionDebt!H19 | I11: =ConstructionDebt!I19 | J11: =ConstructionDebt!J19 | ... CH11: =ConstructionDebt!CH19
A12: Closing balance | B12: $ | C12: =C5-C8-C9 | D12: =D5-D8-D9 | E12: =E5-E8-E9 | F12: =F5-F8-F9 | G12: =G5-G8-G9 | H12: =H5-H8-H9 | I12: =I5-I8-I9 | J12: =J5-J8-J9 | ... CH12: =CH5-CH8-CH9
A13: Net refinance proceeds | B13: $ | C13: =IF(C2=PERM_CONV_M,$C$39*(1-PERM_COSTS_PCT)-C11,0) | D13: =IF(D2=PERM_CONV_M,$C$39*(1-PERM_COSTS_PCT)-D11,0) | E13: =IF(E2=PERM_CONV_M,$C$39*(1-PERM_COSTS_PCT)-E11,0) | F13: =IF(F2=PERM_CONV_M,$C$39*(1-PERM_COSTS_PCT)-F11,0) | G13: =IF(G2=PERM_CONV_M,$C$39*(1-PERM_COSTS_PCT)-G11,0) | H13: =IF(H2=PERM_CONV_M,$C$39*(1-PERM_COSTS_PCT)-H11,0) | I13: =IF(I2=PERM_CONV_M,$C$39*(1-PERM_COSTS_PCT)-I11,0) | J13: =IF(J2=PERM_CONV_M,$C$39*(1-PERM_COSTS_PCT)-J11,0) | ... CH13: =IF(CH2=PERM_CONV_M,$C$39*(1-PERM_COSTS_PCT)-CH11,0)
A29: Sizing at conversion, on T12 NOI ending PERM_CONV_M
A30: Hotel T12 NOI at conversion | B30: $ | C30: =SUM(INDEX(HotelProForma!C11:CH11,PERM_CONV_M-11):INDEX(HotelProForma!C11:CH11,PERM_CONV_M))
A31: Retail T12 NOI at conversion | B31: $ | C31: =SUM(INDEX(RetailProForma!C12:CH12,PERM_CONV_M-11):INDEX(RetailProForma!C12:CH12,PERM_CONV_M))
A32: Combined T12 NOI | B32: $ | C32: =C30+C31
A33: Hotel value at conversion | B33: $ | C33: =C30/HOTEL_CAP
A34: Retail value at conversion | B34: $ | C34: =C31/RETAIL_CAP
A35: LTV size | B35: $ | C35: =PERM_LTV*(C33+C34) | D35: Proceeds are the minimum of the LTV, DSCR, and debt-yield sizes.
A36: PMT factor | B36: $ per $1 | C36: =PMT(PERM_RATE_PCT/12,PERM_AMORT_YRS*12,-1)
A37: DSCR size | B37: $ | C37: =(C32/PERM_DSCR)/C36
A38: Debt-yield size | B38: $ | C38: =C32/PERM_DY
A39: Permanent proceeds | B39: $ | C39: =MIN(C35,C37,C38)

Sheet HotelValuation
A1: HotelValuation
A2: Month | B2: index | C2: =COLUMN()-2 | D2: =COLUMN()-2 | E2: =COLUMN()-2 | F2: =COLUMN()-2 | G2: =COLUMN()-2 | H2: =COLUMN()-2 | I2: =COLUMN()-2 | J2: =COLUMN()-2 | ... CH2: =COLUMN()-2
A3: Date | B3: month-end | C3: =EOMONTH(DATE(2026,1,1),C2-1) | D3: =EOMONTH(DATE(2026,1,1),D2-1) | E3: =EOMONTH(DATE(2026,1,1),E2-1) | F3: =EOMONTH(DATE(2026,1,1),F2-1) | G3: =EOMONTH(DATE(2026,1,1),G2-1) | H3: =EOMONTH(DATE(2026,1,1),H2-1) | I3: =EOMONTH(DATE(2026,1,1),I2-1) | J3: =EOMONTH(DATE(2026,1,1),J2-1) | ... CH3: =EOMONTH(DATE(2026,1,1),CH2-1)
A4: Hotel NOI | B4: $ | C4: =HotelProForma!C11 | D4: =HotelProForma!D11 | E4: =HotelProForma!E11 | F4: =HotelProForma!F11 | G4: =HotelProForma!G11 | H4: =HotelProForma!H11 | I4: =HotelProForma!I11 | J4: =HotelProForma!J11 | ... CH4: =HotelProForma!CH11
A6: T12 NOI at exit | B6: $ | C6: =SUM(INDEX(C4:CH4,EXIT_M-11):INDEX(C4:CH4,EXIT_M)) | D6: Trailing 12 months ending EXIT_M.
A7: Hotel value | B7: $ | C7: =C6/HOTEL_CAP | D7: T12 NOI divided by HOTEL_CAP. No condo cap rate on this sheet.
A9: T12 build-up
A10: Trailing month 1 | B10: month | C10: =INDEX($C$2:$CH$2,EXIT_M-12+1) | D10: =INDEX($C$4:$CH$4,EXIT_M-12+1)
A11: Trailing month 2 | B11: month | C11: =INDEX($C$2:$CH$2,EXIT_M-12+2) | D11: =INDEX($C$4:$CH$4,EXIT_M-12+2)
A12: Trailing month 3 | B12: month | C12: =INDEX($C$2:$CH$2,EXIT_M-12+3) | D12: =INDEX($C$4:$CH$4,EXIT_M-12+3)
A13: Trailing month 4 | B13: month | C13: =INDEX($C$2:$CH$2,EXIT_M-12+4) | D13: =INDEX($C$4:$CH$4,EXIT_M-12+4)
A14: Trailing month 5 | B14: month | C14: =INDEX($C$2:$CH$2,EXIT_M-12+5) | D14: =INDEX($C$4:$CH$4,EXIT_M-12+5)
A15: Trailing month 6 | B15: month | C15: =INDEX($C$2:$CH$2,EXIT_M-12+6) | D15: =INDEX($C$4:$CH$4,EXIT_M-12+6)
A16: Trailing month 7 | B16: month | C16: =INDEX($C$2:$CH$2,EXIT_M-12+7) | D16: =INDEX($C$4:$CH$4,EXIT_M-12+7)
A17: Trailing month 8 | B17: month | C17: =INDEX($C$2:$CH$2,EXIT_M-12+8) | D17: =INDEX($C$4:$CH$4,EXIT_M-12+8)
A18: Trailing month 9 | B18: month | C18: =INDEX($C$2:$CH$2,EXIT_M-12+9) | D18: =INDEX($C$4:$CH$4,EXIT_M-12+9)
A19: Trailing month 10 | B19: month | C19: =INDEX($C$2:$CH$2,EXIT_M-12+10) | D19: =INDEX($C$4:$CH$4,EXIT_M-12+10)
A20: Trailing month 11 | B20: month | C20: =INDEX($C$2:$CH$2,EXIT_M-12+11) | D20: =INDEX($C$4:$CH$4,EXIT_M-12+11)
A21: Trailing month 12 | B21: month | C21: =INDEX($C$2:$CH$2,EXIT_M-12+12) | D21: =INDEX($C$4:$CH$4,EXIT_M-12+12)
A22: T12 build-up sum | B22: $ | C22: =SUM(D10:D21)
A23: Build-up minus T12 | B23: $ | C23: =C22-C6

Sheet RetailValuation
A1: RetailValuation
A2: Month | B2: index | C2: =COLUMN()-2 | D2: =COLUMN()-2 | E2: =COLUMN()-2 | F2: =COLUMN()-2 | G2: =COLUMN()-2 | H2: =COLUMN()-2 | I2: =COLUMN()-2 | J2: =COLUMN()-2 | ... CH2: =COLUMN()-2
A3: Date | B3: month-end | C3: =EOMONTH(DATE(2026,1,1),C2-1) | D3: =EOMONTH(DATE(2026,1,1),D2-1) | E3: =EOMONTH(DATE(2026,1,1),E2-1) | F3: =EOMONTH(DATE(2026,1,1),F2-1) | G3: =EOMONTH(DATE(2026,1,1),G2-1) | H3: =EOMONTH(DATE(2026,1,1),H2-1) | I3: =EOMONTH(DATE(2026,1,1),I2-1) | J3: =EOMONTH(DATE(2026,1,1),J2-1) | ... CH3: =EOMONTH(DATE(2026,1,1),CH2-1)
A4: Retail NOI | B4: $ | C4: =RetailProForma!C12 | D4: =RetailProForma!D12 | E4: =RetailProForma!E12 | F4: =RetailProForma!F12 | G4: =RetailProForma!G12 | H4: =RetailProForma!H12 | I4: =RetailProForma!I12 | J4: =RetailProForma!J12 | ... CH4: =RetailProForma!CH12
A6: T12 NOI at exit | B6: $ | C6: =SUM(INDEX(C4:CH4,EXIT_M-11):INDEX(C4:CH4,EXIT_M)) | D6: Trailing 12 months ending EXIT_M.
A7: Retail value | B7: $ | C7: =C6/RETAIL_CAP | D7: T12 NOI divided by RETAIL_CAP. No condo cap rate on this sheet.
A9: T12 build-up
A10: Trailing month 1 | B10: month | C10: =INDEX($C$2:$CH$2,EXIT_M-12+1) | D10: =INDEX($C$4:$CH$4,EXIT_M-12+1)
A11: Trailing month 2 | B11: month | C11: =INDEX($C$2:$CH$2,EXIT_M-12+2) | D11: =INDEX($C$4:$CH$4,EXIT_M-12+2)
A12: Trailing month 3 | B12: month | C12: =INDEX($C$2:$CH$2,EXIT_M-12+3) | D12: =INDEX($C$4:$CH$4,EXIT_M-12+3)
A13: Trailing month 4 | B13: month | C13: =INDEX($C$2:$CH$2,EXIT_M-12+4) | D13: =INDEX($C$4:$CH$4,EXIT_M-12+4)
A14: Trailing month 5 | B14: month | C14: =INDEX($C$2:$CH$2,EXIT_M-12+5) | D14: =INDEX($C$4:$CH$4,EXIT_M-12+5)
A15: Trailing month 6 | B15: month | C15: =INDEX($C$2:$CH$2,EXIT_M-12+6) | D15: =INDEX($C$4:$CH$4,EXIT_M-12+6)
A16: Trailing month 7 | B16: month | C16: =INDEX($C$2:$CH$2,EXIT_M-12+7) | D16: =INDEX($C$4:$CH$4,EXIT_M-12+7)
A17: Trailing month 8 | B17: month | C17: =INDEX($C$2:$CH$2,EXIT_M-12+8) | D17: =INDEX($C$4:$CH$4,EXIT_M-12+8)
A18: Trailing month 9 | B18: month | C18: =INDEX($C$2:$CH$2,EXIT_M-12+9) | D18: =INDEX($C$4:$CH$4,EXIT_M-12+9)
A19: Trailing month 10 | B19: month | C19: =INDEX($C$2:$CH$2,EXIT_M-12+10) | D19: =INDEX($C$4:$CH$4,EXIT_M-12+10)
A20: Trailing month 11 | B20: month | C20: =INDEX($C$2:$CH$2,EXIT_M-12+11) | D20: =INDEX($C$4:$CH$4,EXIT_M-12+11)
A21: Trailing month 12 | B21: month | C21: =INDEX($C$2:$CH$2,EXIT_M-12+12) | D21: =INDEX($C$4:$CH$4,EXIT_M-12+12)
A22: T12 build-up sum | B22: $ | C22: =SUM(D10:D21)
A23: Build-up minus T12 | B23: $ | C23: =C22-C6

Sheet ProjectCF
A1: ProjectCF
A2: Month | B2: index | C2: =COLUMN()-2 | D2: =COLUMN()-2 | E2: =COLUMN()-2 | F2: =COLUMN()-2 | G2: =COLUMN()-2 | H2: =COLUMN()-2 | I2: =COLUMN()-2 | J2: =COLUMN()-2 | ... CH2: =COLUMN()-2
A3: Date | B3: month-end | C3: =EOMONTH(DATE(2026,1,1),C2-1) | D3: =EOMONTH(DATE(2026,1,1),D2-1) | E3: =EOMONTH(DATE(2026,1,1),E2-1) | F3: =EOMONTH(DATE(2026,1,1),F2-1) | G3: =EOMONTH(DATE(2026,1,1),G2-1) | H3: =EOMONTH(DATE(2026,1,1),H2-1) | I3: =EOMONTH(DATE(2026,1,1),I2-1) | J3: =EOMONTH(DATE(2026,1,1),J2-1) | ... CH3: =EOMONTH(DATE(2026,1,1),CH2-1)
A4: Condo net revenue | B4: $ | C4: =CondoSellout!C16 | D4: =CondoSellout!D16 | E4: =CondoSellout!E16 | F4: =CondoSellout!F16 | G4: =CondoSellout!G16 | H4: =CondoSellout!H16 | I4: =CondoSellout!I16 | J4: =CondoSellout!J16 | ... CH4: =CondoSellout!CH16
A5: Condo applied to construction debt | B5: $ | C5: =ConstructionDebt!C18 | D5: =ConstructionDebt!D18 | E5: =ConstructionDebt!E18 | F5: =ConstructionDebt!F18 | G5: =ConstructionDebt!G18 | H5: =ConstructionDebt!H18 | I5: =ConstructionDebt!I18 | J5: =ConstructionDebt!J18 | ... CH5: =ConstructionDebt!CH18
A6: Condo net after construction paydown | B6: $ | C6: =C4-C5 | D6: =D4-D5 | E6: =E4-E5 | F6: =F4-F5 | G6: =G4-G5 | H6: =H4-H5 | I6: =I4-I5 | J6: =J4-J5 | ... CH6: =CH4-CH5
A7: Hotel NOI | B7: $ | C7: =HotelProForma!C11 | D7: =HotelProForma!D11 | E7: =HotelProForma!E11 | F7: =HotelProForma!F11 | G7: =HotelProForma!G11 | H7: =HotelProForma!H11 | I7: =HotelProForma!I11 | J7: =HotelProForma!J11 | ... CH7: =HotelProForma!CH11
A8: Retail NOI | B8: $ | C8: =RetailProForma!C12 | D8: =RetailProForma!D12 | E8: =RetailProForma!E12 | F8: =RetailProForma!F12 | G8: =RetailProForma!G12 | H8: =RetailProForma!H12 | I8: =RetailProForma!I12 | J8: =RetailProForma!J12 | ... CH8: =RetailProForma!CH12
A9: Permanent debt service | B9: $ | C9: =PermanentDebt!C10 | D9: =PermanentDebt!D10 | E9: =PermanentDebt!E10 | F9: =PermanentDebt!F10 | G9: =PermanentDebt!G10 | H9: =PermanentDebt!H10 | I9: =PermanentDebt!I10 | J9: =PermanentDebt!J10 | ... CH9: =PermanentDebt!CH10
A10: Refinance net proceeds | B10: $ | C10: =PermanentDebt!C13 | D10: =PermanentDebt!D13 | E10: =PermanentDebt!E13 | F10: =PermanentDebt!F13 | G10: =PermanentDebt!G13 | H10: =PermanentDebt!H13 | I10: =PermanentDebt!I13 | J10: =PermanentDebt!J13 | ... CH10: =PermanentDebt!CH13
A11: Terminal net proceeds | B11: $ | C11: =IF(C2=EXIT_M,(HotelValuation!$C$7+RetailValuation!$C$7)*(1-SELL_COST_PCT)-PermanentDebt!C9,0) | D11: =IF(D2=EXIT_M,(HotelValuation!$C$7+RetailValuation!$C$7)*(1-SELL_COST_PCT)-PermanentDebt!D9,0) | E11: =IF(E2=EXIT_M,(HotelValuation!$C$7+RetailValuation!$C$7)*(1-SELL_COST_PCT)-PermanentDebt!E9,0) | F11: =IF(F2=EXIT_M,(HotelValuation!$C$7+RetailValuation!$C$7)*(1-SELL_COST_PCT)-PermanentDebt!F9,0) | G11: =IF(G2=EXIT_M,(HotelValuation!$C$7+RetailValuation!$C$7)*(1-SELL_COST_PCT)-PermanentDebt!G9,0) | H11: =IF(H2=EXIT_M,(HotelValuation!$C$7+RetailValuation!$C$7)*(1-SELL_COST_PCT)-PermanentDebt!H9,0) | I11: =IF(I2=EXIT_M,(HotelValuation!$C$7+RetailValuation!$C$7)*(1-SELL_COST_PCT)-PermanentDebt!I9,0) | J11: =IF(J2=EXIT_M,(HotelValuation!$C$7+RetailValuation!$C$7)*(1-SELL_COST_PCT)-PermanentDebt!J9,0) | ... CH11: =IF(CH2=EXIT_M,(HotelValuation!$C$7+RetailValuation!$C$7)*(1-SELL_COST_PCT)-PermanentDebt!CH9,0)
A12: Distributable cash | B12: $ | C12: =C6+C7+C8-C9+C10+C11 | D12: =D6+D7+D8-D9+D10+D11 | E12: =E6+E7+E8-E9+E10+E11 | F12: =F6+F7+F8-F9+F10+F11 | G12: =G6+G7+G8-G9+G10+G11 | H12: =H6+H7+H8-H9+H10+H11 | I12: =I6+I7+I8-I9+I10+I11 | J12: =J6+J7+J8-J9+J10+J11 | ... CH12: =CH6+CH7+CH8-CH9+CH10+CH11
A13: Equity contribution | B13: $ | C13: =ConstructionDebt!C8 | D13: =ConstructionDebt!D8 | E13: =ConstructionDebt!E8 | F13: =ConstructionDebt!F8 | G13: =ConstructionDebt!G8 | H13: =ConstructionDebt!H8 | I13: =ConstructionDebt!I8 | J13: =ConstructionDebt!J8 | ... CH13: =ConstructionDebt!CH8
A14: Waterfall tier 1 | B14: $ | C14: =Waterfall!C9 | D14: =Waterfall!D9 | E14: =Waterfall!E9 | F14: =Waterfall!F9 | G14: =Waterfall!G9 | H14: =Waterfall!H9 | I14: =Waterfall!I9 | J14: =Waterfall!J9 | ... CH14: =Waterfall!CH9
A15: Waterfall tier 2 | B15: $ | C15: =Waterfall!C20 | D15: =Waterfall!D20 | E15: =Waterfall!E20 | F15: =Waterfall!F20 | G15: =Waterfall!G20 | H15: =Waterfall!H20 | I15: =Waterfall!I20 | J15: =Waterfall!J20 | ... CH15: =Waterfall!CH20
A16: Waterfall tier 3 | B16: $ | C16: =Waterfall!C28 | D16: =Waterfall!D28 | E16: =Waterfall!E28 | F16: =Waterfall!F28 | G16: =Waterfall!G28 | H16: =Waterfall!H28 | I16: =Waterfall!I28 | J16: =Waterfall!J28 | ... CH16: =Waterfall!CH28
A17: Waterfall tier 4 | B17: $ | C17: =Waterfall!C33 | D17: =Waterfall!D33 | E17: =Waterfall!E33 | F17: =Waterfall!F33 | G17: =Waterfall!G33 | H17: =Waterfall!H33 | I17: =Waterfall!I33 | J17: =Waterfall!J33 | ... CH17: =Waterfall!CH33
A18: Retained cash | B18: $ | C18: =C12-(C14+C15+C16+C17) | D18: =D12-(D14+D15+D16+D17) | E18: =E12-(E14+E15+E16+E17) | F18: =F12-(F14+F15+F16+F17) | G18: =G12-(G14+G15+G16+G17) | H18: =H12-(H14+H15+H16+H17) | I18: =I12-(I14+I15+I16+I17) | J18: =J12-(J14+J15+J16+J17) | ... CH18: =CH12-(CH14+CH15+CH16+CH17)

Sheet Waterfall
A1: Waterfall
A2: Month | B2: index | C2: =COLUMN()-2 | D2: =COLUMN()-2 | E2: =COLUMN()-2 | F2: =COLUMN()-2 | G2: =COLUMN()-2 | H2: =COLUMN()-2 | I2: =COLUMN()-2 | J2: =COLUMN()-2 | ... CH2: =COLUMN()-2
A3: Date | B3: month-end | C3: =EOMONTH(DATE(2026,1,1),C2-1) | D3: =EOMONTH(DATE(2026,1,1),D2-1) | E3: =EOMONTH(DATE(2026,1,1),E2-1) | F3: =EOMONTH(DATE(2026,1,1),F2-1) | G3: =EOMONTH(DATE(2026,1,1),G2-1) | H3: =EOMONTH(DATE(2026,1,1),H2-1) | I3: =EOMONTH(DATE(2026,1,1),I2-1) | J3: =EOMONTH(DATE(2026,1,1),J2-1) | ... CH3: =EOMONTH(DATE(2026,1,1),CH2-1)
